Workbook

Sheet 0812
A1: LH | B1: DESTINO | C1: FANOUT | D1: DOCA | E1: CPT | G1: TOTAL DE CARROS EM CURSO PARA O T1
A2: LT0PC901TO8Z1 | B2: GUARATINGUETÁ | C2: LSP-33 | D2: 17 | E2: 0.25 | G2: HUB | H2: 17
A3: LT0PC901TOAZ1 | B3: LIMEIRA | C3: LSP-24 | D3: 37 | E3: 0.25 | G3: SOCS | H3: 11
A4: LT0PC901TO8L1 | B4: REGISTRO | C4: LSP-40 | D4: 16 | E4: 0.25
A5: LT0PC901TPG11 | B5: SÃO BERNARDO DO CAMPO | C5: LSP-79 | D5: 27 | E5: 0.25 | G5: NÃO DOCADO | H5: 1
A6: LT0PC901TOBH1 | B6: VÁRZEA PAULISTA | C6: LSP-61 | D6: 48 | E6: 0.25 | G6: MOTIVO: | H6: NÃO CHEGOU
A7: LT0PC901TTRB1 | B7: ATIBAIA | C7: LSP-87 | D7: 8 | E7: 0.27083333 | G7: DESTINO | H7: ITAPEVI LSP-41
A8: LT0PC901TQJ72 | B8: EMBU DAS ARTES | C8: LSP-36 | D8: 33 | E8: 0.27083333
A9: LT0PC901TN9V1 | B9: TAUBATÉ | C9: LSP-08 | D9: 12 | E9: 0.27083333
A10: LT0PC801TVNO1 | B10: BA SIMOES FILHO | C10: SOC-BA2 | D10: 88 | E10: 0.29166667
A11: LT0PC801TVNQ2 | B11: BA SIMOES FILHO | C11: SOC-BA2 | D11: 89 | E11: 0.29166667
A12: LT0PC801TVY72 | B12: GOIÂNIA 02 | C12: SOC-GO2 | D12: 87 | E12: 0.29166667
A13: LT0PC801TNYQ1 | B13: MG BETIM | C13: SOC-MG2 | D13: 91 | E13: 0.29166667
A14: LT0PC801TNYS2 | B14: MG BETIM | C14: SOC-MG2 | D14: 42 | E14: 0.29166667
A15: LT0PC901TV8V1 | B15: BARUERI | C15: LSP-81 | D15: 6 | E15: 0.29166667
A16: LT0PC901TWTU1 | B16: JUNDIAI | C16: LSP-100 | D16: 7 | E16: 0.29166667
A17: LT0PC901TPP11 | B17: PIRACICABA | C17: LSP-62 | D17: 26 | E17: 0.29166667
A18: LT0PC901TQIX2 | B18: SANTOS PRAIA GRANDE 02 | C18: LSP-63 | D18: 29 | E18: 0.29166667
A19: LT0PC901TQIV1 | B19: SANTOS PRAIA GRANDE 02 | C19: LSP-63 | D19: 28 | E19: 0.29166667
... A23: LT0PC901TQHX1 | B23: GUARUJA | C23: LSP-06 | D23: 7 | E23: 0.3125
A24: LT0PC901TN9N1 | B24: ITAPEVI | C24: LSP-41 | D24: - | E24: 0.3125
A25: LT0PC901TQHR1 | B25: ZIMBA | C25: LSP-74 | D25: 14 | E25: 0.3125
A26: LT0PC901TNS21 | B26: SÃO JOSÉ DOS CAMPOS | C26: LSP-04 | D26: 22 | E26: 0.3125
A27: LT0PC901TNRC1 | B27: MOOCA | C27: LSP-13 | D27: 13 | E27: 0.3125
A28: LT0PC801TRQU2 | B28: RJ DUQUE DE CAXIAS | C28: SOC-RJ2 | D28: 96 | E28: 0.33333333
A29: LT1PC901U2E01 | B29: RJ DUQUE DE CAXIAS | C29: SOC-RJ2 | D29: 97 | E29: 0.33333333
A30: LT1PC901U2DT1 | B30: CRAVINHOS | C30: SOC-SP5 | D30: 94 | E30: 0.33333333
A31: LT1PC901U2E31 | B31: MG BETIM | C31: SOC-MG2 | D31: 90 | E31: 0.41666667
A32: LT1PC901U2DU1 | B32: CRAVINHOS | C32: SOC-SP5 | D32: 49 | E32: 0.41666667

Sheet 0912
A1: LH | B1: DESTINO | C1: FANOUT | D1: DOCA | E1: CPT | G1: TOTAL DE CARROS EM CURSO PARA O T1
A2: LT0PCA01TQHD1 | B2: OSASCO | C2: LSP-60 | E2: 0.22916667
A3: LT0PCA01TO901 | B3: GUARATINGUETÁ | C3: LSP-33 | D3: 17 | E3: 0.25 | G3: HUB | H3: 16
A4: LT0PCA01TOB01 | B4: LIMEIRA | C4: LSP-24 | D4: 35 | E4: 0.25 | G4: SOCS | H4: 8
A5: LT0PCA01TO8M1 | B5: REGISTRO | C5: LSP-40 | D5: 6 | E5: 0.25
A6: LT0PCA01TPG21 | B6: SÃO BERNARDO DO CAMPO | C6: LSP-79 | D6: 29 | E6: 0.25 | G6: NÃO DOCADO | H6: 3 HUBS 8 SOC'S
A7: LT0PCA01TOBG1 | B7: VÁRZEA PAULISTA | C7: LSP-61 | D7: 47 | E7: 0.25 | G7: MOTIVO: | H7: Os hubs não foram localizados pelo pátio e os intersocs são de CPT's estendidos que ficam selecionados para Telescópica
A8: LT0PCA01TTRC1 | B8: ATIBAIA | C8: LSP-87 | D8: 14 | E8: 0.27083333 | G8: DESTINO | H8: LSP-60 LSP-100 LRS-03 SP5 SP2 MG2 MG2 BA2 GO2 GO2 BA2
A9: LT0PCA01TO9F1 | B9: TAUBATÉ | C9: LSP-08 | D9: 7 | E9: 0.27083333
A10: LT0PC901TVNS1 | B10: BA SIMOES FILHO | C10: SOC-BA2 | D10: 46 | E10: 0.29166667
A11: LT0PC901TVY61 | B11: GO GOIÂNIA 02 | C11: SOC-GO2 | D11: 21 | E11: 0.29166667
A12: LT0PC901TVY82 | B12: GO GOIÂNIA 02 | C12: SOC-GO2 | D12: 49 | E12: 0.29166667
A13: LT0PC901TNYT2 | B13: MG BETIM | C13: SOC-MG2 | D13: 91 | E13: 0.29166667
A14: LT0PC901TN8K2 | B14: MG BETIM | C14: SOC-MG2 | D14: 90 | E14: 0.29166667
A15: LT1PC901U2EQ1 | B15: GO GOIÂNIA 02 | C15: SOC-MG2 | D15: 48 | E15: 0.29166667
A16: LT0PCA01TV8U1 | B16: BARUERI | C16: LSP-81 | D16: 12 | E16: 0.29166667
A17: LT0PCA01TPP21 | B17: PIRACICABA | C17: LSP-62 | D17: 28 | E17: 0.29166667
A18: LT0PCA01TQGZ2 | B18: JURUBATUBA | C18: LSP-16 | D18: 19 | E18: 0.29166667
A19: LT0PCA01TQJ31 | B19: PRAIA GRANDE 02 | C19: LSP-63 | D19: 27 | E19: 0.29166667
A20: LT0PCA01TP401 | B20: SANTANA | C20: SOC-SP2 | D20: 33 | E20: 0.29166667
... A25: LT1PCA01U39U1 | B25: BA SIMOES FILHO | C25: SOC-BA2 | D25: 88 | E25: 0.33333333

Sheet 1012
A1: LH | B1: DESTINO | C1: FANOUT | D1: DOCA | E1: CPT | G1: TOTAL DE CARROS EM CURSO PARA O T1
A2: LT0PCB01TO911 | B2: GUARATINGUETA | C2: LSP-33 | D2: 13 | E2: 0.25 | G2: HUB | H2: 12
A3: LT0PCB01TOB11 | B3: LIMEIRA | C3: LSP-24 | D3: NO SHOW | E3: 0.25 | G3: SOCS | H3: 8
A4: LT0PCB01TO8N1 | B4: REGISTRO | C4: LSP-40 | D4: 5 | E4: 0.25
A5: LT0PCB01TPG31 | B5: SÃO BERNARDO DO CAMPO | C5: LSP-79 | D5: NO SHOW | E5: 0.25 | G5: NÃO DOCADO | H5: 18
A6: LT0PCB01TOBI1 | B6: VÁRZEA PAULISTA | C6: LSP-61 | D6: 45 | E6: 0.25 | G6: MOTIVO: HUBS não foram docados por não terem chegado a tempo do nosso turno SOC's não foram docados por falta de pacotes em piso e a maioria de CPT estendido que são direcionados para a telescópica
A7: LT1PCB01U4061 | B7: GRAVATAI | C7: SOC-RS2 | D7: 18 | E7: 0.25 | G7: DESTINO: HUB'S: LSP-87, LSP-36, LSP-63, LES-09 SOC'S: SP5, GO2, BA2, MG2, RJ2
A8: LT0PCB01TTRD1 | B8: ATIBAIA | C8: LSP-87 | D8: NÃO CHEGOU | E8: 0.27083333
A9: LT0PCB01TN9W1 | B9: TAUBATÉ | C9: LSP-08 | D9: 12 | E9: 0.27083333
A10: LT0PCB01TQJA1 | B10: EMBU DAS ARTES | C10: LSP-36 | D10: NÃO CHEGOU | E10: 0.27083333
A11: LT0PCA01TVNT1 | B11: BA SIMOES FILHO | C11: SOC-BA2 | D11: 89 | E11: 0.29166667
A12: LT0PCA01TVNX3 | B12: BA SIMOES FILHO | C12: SOC-BA2 | D12: 88 | E12: 0.29166667
A13: LT0PC901TVYB3 | B13: GO-GOIÂNIA | C13: SOC-GO2 | D13: 87 | E13: 0.29166667
A14: LT0PCA01TRRE2 | B14: RJ DUQUE DE CAXIAS | C14: SOC-RJ2 | D14: 47 | E14: 0.29166667
A15: LT0PCA01TNZ31 | B15: MG-BETIM | C15: SOC-MG2 | D15: 91 | E15: 0.29166667
A16: LT0PCA01TNZ52 | B16: MG-BETIM | C16: SOC-MG2 | D16: 90 | E16: 0.29166667
A17: LT0PCB01TV8W1 | B17: BARUERI | C17: LSP-81 | D17: 14 | E17: 0.29166667
A18: LT0PCB01TWTW1 | B18: JUNDIAI | C18: LSP-100 | D18: 8 | E18: 0.29166667
A19: LT0PCB01TQGU1 | B19: JURUBATUBA | C19: LSP-16 | D19: 19 | E19: 0.29166667
A20: LT0PCB01TPP31 | B20: PIRACICABA | C20: LSP-63 | D20: NÃO CHEGOU | E20: 0.29166667
A21: LT0PCB01TQIC1 | B21: PRAIA GRANDE | C21: LSP-09 | D21: 26 | E21: 0.3125
A22: LT0PCB01TNS31 | B22: SÃO JOSÉ CAMPOS | C22: LSP-04 | D22: 15 | E22: 0.3125
A23: LT0PCB01TP411 | B23: SANTANA | C23: SOC-SP2 | D23: 33 | E23: 0.29166667
A24: LT0PCB01TQHZ1 | B24: GUARUJA | C24: LSP-06 | D24: 7 | E24: 0.3125
A25: LT0PCB01TQIY2 | B25: PRAIA GRANDE 02 | C25: LSP-63 | D25: 23 | E25: 0.29166667
A26: LT0PCB01TQHT1 | B26: ITAQUA ZIMBA | C26: LSP-74 | D26: 32 | E26: 0.3125
A27: LT0PCA01TO1U2 | B27: CRAVINHOS | C27: SOC -SP5 | D27: NÃO DOCOU | E27: 0.29166667
A28: LT0PCA01TO1S1 | B28: CRAVINHOS | C28: SOC -SP5 | D28: NÃO DOCOU | E28: 0.29166667
A29: LT0PCA01TVY91 | B29: GOIÂNIA | C29: SOC-GO2 | D29: NÃO DOCOU | E29: 0.29166667
A30: LT0PCA01TVYA2 | B30: GOIÂNIA | C30: SOC-GO2 | D30: NÃO DOCOU | E30: 0.29166667
A31: LT0PCA01TVYC3 | B31: GOIÂNIA | C31: SOC-GO2 | D31: NÃO DOCOU | E31: 0.29166667
A32: LT0PCA01TRRG3 | B32: RJ DUQUE DE CAXIAS | C32: SOC-RJ2 | D32: NÃO DOCOU | E32: 0.29166667
A33: LT0PCA01TRRI4 | B33: RJ DUQUE DE CAXIAS | C33: SOC-RJ2 | D33: NÃO DOCOU | E33: 0.29166667
A34: LT0PCA01TN8P1 | B34: CRAVINHOS | C34: SOC-SP5 | D34: NÃO DOCOU | E34: 0.29166667
A35: LT0PCA01TNZ73 | B35: MG-BETIM | C35: SOC-MG2 | D35: NÃO DOCOU | E35: 0.29166667
A36: LT0PCA01TRRK5 | B36: RJ DUQUE DE CAXIAS | C36: SOC-RJ2 | D36: NÃO DOCOU | E36: 0.29166667
A37: LT0PCA01TRRC1 | B37: RJ DUQUE DE CAXIAS | C37: SOC-RJ2 | D37: NÃO DOCOU | E37: 0.29166667
A38: LT1PCB01U4081 | B38: GOIÂNIA | C38: SOC-GO2 | D38: NÃO DOCOU | E38: 0.33333333
... A42: LT1PCB01U4TW1 | B42: VIANA | C42: LES-09 | D42: NÃO CHEGOU | E42: 0.27083333

Sheet 1112
A1: LH | B1: DESTINO | C1: FANOUT | D1: DOCA | E1: CPT | G1: TOTAL DE CARROS EM CURSO PARA O T1 | H1: 18
A2: LT0PCC01TO8O1 | B2: REGISTRO | C2: LSP-40 | D2: 6 | E2: 0.25 | G2: HUB | H2: 14
A3: LT0PCC01TO921 | B3: GUARATINGUETÁ | C3: LSP-33 | D3: 17 | E3: 0.25 | G3: SOCS | H3: 4
A4: LT0PCC01TOB21 | B4: LIMEIRA | C4: LSP-24 | D4: 41 | E4: 0.25
A5: LT0PCC01TOBJ1 | B5: VÁRZEA PAULISTA | C5: LSP-61 | D5: 46 | E5: 0.25 | G5: NÃO DOCADO | H5: 6
A6: LT0PCC01TPG41 | B6: SÃO BERNARDO DO CAMPO | C6: LSP-79 | D6: 28 | E6: 0.25 | G6: MOTIVO: EMBU DAS ARTES LSP-36 (ATRASO NA ETA VAI CHEGAR 06H) ITAPEVI LSP-41 (AGUARDANDO DESCARGA NO HUB) RJ2 (NÃO DOCADO) BA2 (FALTA DE PACOTES NO PISO) SP5 (FALTA DE PACOTES NO PISO) SP2 (NÃO CHEGOU)
A7: LT1PCC01U4GX1 | B7: RJ DUQUE DE CAXIAS | C7: RJ2 | D7: NÃO DOCOU | E7: 0.25 | G7: DESTINO: LSP-36, LSP-41, RJ2, BA2, SP5, SP2
A8: LT0PCC01TTRE1 | B8: ATIBAIA | C8: LSP-87 | D8: 15 | E8: 0.27083333
A9: LT0PCC01TN9X1 | B9: TAUBATÉ | C9: LSP-08 | D9: 13 | E9: 0.27083333
A10: LT0PCC01TQJB1 | B10: EMBU DAS ARTES | C10: LSP-36 | D10: NÃO CHEGOU | E10: 0.27083333
A11: LT0PCB01TVO23 | B11: BA SIMOES FILHO | C11: BA2 | D11: NÃO CHEGOU | E11: 0.29166667
A12: LT0PCB01TRR03 | B12: RJ DUQUE DE CAXIAS | C12: RJ2 | D12: 97 | E12: 0.29166667
A13: LT0PCB01TVNY1 | B13: BA SIMOES FILHO | C13: BA2 | D13: 89 | E13: 0.29166667
A14: LT0PCB01TNZ41 | B14: MG BETIM | C14: MG2 | D14: 7 | E14: 0.29166667
A15: LT0PCB01TNZ83 | B15: MG BETIM | C15: MG2 | D15: 48 | E15: 0.33333333
A16: LT0PCB01TNZA4 | B16: MG BETIM | C16: MG2 | D16: 90 | E16: 0.29166667
A17: LT0PCB01TO1K2 | B17: CRAVINHOS | C17: SP5 | D17: NÃO CHEGOU | E17: 0.29166667
A18: LT0PCC01TPP41 | B18: PIRACICABA | C18: LSP-62 | D18: 29 | E18: 0.29166667
A19: LT0PCC01TV8X1 | B19: BARUERI | C19: LSP-81 | D19: 12 | E19: 0.29166667
A20: LT0PCC01TP421 | B20: SANTANA | C20: SP2 | D20: NÃO CHEGOU | E20: 0.29166667
A21: LT0PCC01TQH01 | B21: JURUBATUBA | C21: LSP-16 | D21: 19 | E21: 0.29166667
A22: LT0PCC01TQH22 | B22: JURUBATUBA | C22: LSP-16 | D22: 18 | E22: 0.29166667
A23: LT0PCC01TQHU1 | B23: ITAQUA ZIMBA | C23: LSP-74 | D23: 33 | E23: 0.3125
A24: LT0PCC01TQI01 | B24: GUARUJA | C24: LSP-06 | D24: 9 | E24: 0.3125
A25: LT0PCC01TO5C1 | B25: ITAPEVI | C25: LSP-41 | D25: NÃO DOCOU | E25: 0.3125
A26: LT0PCC01TVXL3 | B26: GOIÂNIA | C26: GO2 | D26: 87 | E26: 0.66666667
A27: LT0PCC01TVN73 | B27: BA SIMOES FILHO | C27: BA2 | D27: 88 | E27: 0.66666667
A28: LT0PCC01TNRI1 | B28: MOOCA | C28: LSP-13 | D28: 14 | E28: 0.3125
A29: LT0PCB01TO1Z2 | B29: CRAVINHOS | C29: SP5 | D29: 47 | E29: 0.125
A30: LT0PCC01TVIP1 | B30: PE JABOATÃO | C30: PE2 | D30: 22 | E30: 0.20833333

Sheet 1212
A1: LH | B1: DESTINO | C1: FANOUT | D1: DOCA | E1: CPT | G1: TOTAL DE CARROS EM CURSO PARA O T1
A2: LT0PCD01TTRF1 | B2: ATIBAIA | C2: LSP-87 | D2: 13 | E2: 0.27083333 | G2: HUB | H2: 15
A3: LT0PCD01TQJC1 | B3: EMBU DAS ARTES | C3: LSP-36 | D3: 34 | E3: 0.27083333 | G3: SOCS | H3: 4
A4: LT0PCD01TO9G1 | B4: TAUBATE | C4: LSP-08 | D4: 14 | E4: 0.27083333
A5: LT0PCC01TVNZ1 | B5: BA SIMOES FILHO | C5: BA2 | D5: 89 | E5: 0.29166667 | G5: NÃO DOCADO | H5: 1
A6: LT0PCC01TVYH2 | B6: GOIANIA 02 | C6: GO2 | D6: 49 | E6: 0.29166667 | G6: MOTIVO: | H6: NÃO CHEGOU
A7: LT1PCC01U52M1 | B7: GOIANIA 02 | C7: GO2 | D7: 86 | E7: 0.29166667 | G7: DESTINO | H7: ITAQUA-ZIMBA LSP-74
A8: LT0PCC01TN8F1 | B8: MG BETIM | C8: MG2 | D8: 90 | E8: 0.29166667
A9: LT0PCD01TV8Y1 | B9: BARUERI | C9: LSP-81 | D9: 12 | E9: 0.29166667
A10: LT0PCD01TQJ41 | B10: PRAIA GRANDE 02 | C10: LSP-63 | D10: 26 | E10: 0.29166667
A11: LT0PCD01TQI11 | B11: GUARUJA | C11: LSP-06 | D11: 9 | E11: 0.3125
A12: LT0PCD01TNS41 | B12: SÃO JOSÉ DOS CAMPOS | C12: LSP-04 | D12: 20 | E12: 0.3125
A13: LT0PCD01TQIK1 | B13: SÃO JOSÉ DOS CAMPOS | C13: LSP-04 | D13: 22 | E13: 0.3125
A14: LT0PCD01TO5D1 | B14: ITAPEVI | C14: LSP-41 | D14: 5 | E14: 0.3125
A15: LT0PCD01TPP51 | B15: PIRACICABA | C15: LSP-62 | D15: 27 | E15: 0.3125
A16: LT0PCD01TWTY1 | B16: JUNDIAI | C16: LSP-100 | D16: 7 | E16: 0.29166667
A17: LT0PCD01TNRV1 | B17: MAUÁ | C17: LSP-64 | D17: 14 | E17: 0.29166667
A18: LT0PCD01TQGL1 | B18: JARDIM ADRIANA | C18: LSP-12 | D18: 8 | E18: 0.33333333
A19: LT0PCD01TQIT1 | B19: GUARULHOS | C19: LSP-77 | D19: 28 | E19: 0.33333333
A20: LT0PCD01TTJS1 | B20: EMBU DAS ARTES 02 | C20: LSP-96 | D20: 32 | E20: 0.33333333

Sheet 1512
A1: LH | B1: DESTINO | C1: FANOUT | D1: DOCA | E1: CPT | G1: TOTAL DE CARROS EM CURSO PARA O T1
A2: LT0PCG01UBY81 | B2: REGISTRO | C2: LSP-40 | D2: 16 | E2: 0.25 | G2: HUB | H2: 14
A3: LT0PCG01UBYJ1 | B3: GUARATINGUETÁ | C3: LSP-33 | D3: 14 | E3: 0.25 | G3: SOCS | H3: 5
A4: LT0PCG01UBZK1 | B4: LIMEIRA | C4: LSP-24 | D4: 38 | E4: 0.25
A5: LT0PCG01UBZT1 | B5: VÁRZEA PAULISTA | C5: LSP-61 | D5: 49 | E5: 0.25 | G5: NÃO DOCADO | H5: 10
A6: LT0PCG01UCJ71 | B6: SÃO BERNARDO DO CAMPO | C6: LSP-79 | D6: 29 | E6: 0.25 | G6: MOTIVO: não havia chegado no pátio em tempo hábil
A7: LT0PCG01UCX01 | B7: SOC GUARULHOS | C7: SP6 | D7: 27 | E7: 0.25 | G7: DESTINO: LSP-36, LSP-62, LSP-63, LSP-16, LSP-74, MG2, LSP-100, LSP-09, LSP-13, LSP-19
A8: LT0PCG01UHUF1 | B8: PE JABOATÃO DOS GUARARAPES | C8: PE2 | D8: 23 | E8: 0.25
A9: LT0PCG01UBUU1 | B9: SOC LOUVEIRA | C9: SP7 | D9: 33 | E9: 0.25
A10: LT0PCG01U88B1 | B10: TAUBATÉ | C10: LSP-08 | D10: 8 | E10: 0.27083333
A11: LT0PCG01UD5H1 | B11: EMBU DAS ARTES | C11: LSP-36 | D11: 32 | E11: 0.27083333
A12: LT0PCG01UG6N1 | B12: ATIBAIA | C12: LSP-81 | D12: 17 | E12: 0.27083333
A13: LT0PCF01UBUE1 | B13: CRAVINHOS | C13: SP5 | D13: 94 | E13: 0.29166667
A14: LT0PCG01UD422 | B14: JURUBATUBA | C14: LSP-16 | D14: 9 | E14: 0.29166667
A15: LT0PCG01UK391 | B15: BARUERI | C15: LSP-81 | D15: 12 | E15: 0.29166667
A16: LT0PCG01U8851 | B16: ITAPEVI | C16: LSP-41 | D16: 15 | E16: 0.3125
A17: LT0PCG01UD591 | B17: SANTOS PRAIA GRANDE 02 | C17: LSP-63 | D17: 25 | E17: 0.3125
A18: LT0PCG01UD4L1 | B18: GUARUJÁ | C18: LSP-06 | D18: 5 | E18: 0.3125
A19: LT0PCG01UD4S2 | B19: SANTOS PRAIA GRANDE | C19: LSP-09 | D19: 28 | E19: 0.3125
A20: LT0PCG01UBS52 | B20: MG BETIM | C20: MG2 | D20: 48 | E20: 0.66666667

Sheet 1612
A1: LH | B1: DESTINO | C1: FANOUT | D1: DOCA | E1: CPT | G1: TOTAL DE CARROS EM CURSO PARA O T1 | H1: =SUM(H2,H3) -> 22
A2: LT0PCH01UBYK1 | B2: GUARATINGUETÁ | C2: LSP-33 | D2: 14 | E2: 0.25 | G2: HUB | H2: 13
A3: LT0PCH01UBZL1 | B3: LIMEIRA | C3: LSP-24 | D3: 38 | E3: 0.25 | G3: SOCS | H3: 9
A4: LT0PCH01UBY91 | B4: REGISTRO | C4: LSP-40 | D4: 7 | E4: 0.25
A5: LT0PCH01UCJ81 | B5: SÃO BERNARDO DO CAMPO | C5: LSP-79 | D5: 27 | E5: 0.25 | G5: NÃO DOCADO | H5: 8
A6: LT0PCH01UBZU1 | B6: VARZEA PAULISTA | C6: LSP-61 | D6: 46 | E6: 0.25 | G6: MOTIVO: não havia chegado no pátio em tempo hábil SOCS DE CPT LONGO NÃO CHAMADOS PELA TELESCÓPICA
A7: LT0PCH01UBTC1 | B7: CURITIBA | C7: PR1 | D7: 48 | E7: 0.25 | G7: DESTINO: RJ2, LSP-100, LSP-62, LSP-16, LSP-63, LSP-06, LSP-74
A8: LT0PCH01UI9P1 | B8: GRAVATAI | C8: RS2 | D8: 25 | E8: 0.25
A9: LT0PCH01UBUV1 | B9: LOUVEIRA | C9: SP7 | D9: 32 | E9: 0.25
A10: LT0PCH01UD5J1 | B10: EMBU DAS ARTES | C10: LSP-36 | D10: 13 | E10: 0.27083333
A11: LT0PCH01UBYU1 | B11: TAUBATÉ | C11: LSP-08 | D11: 8 | E11: 0.27083333
A12: LT0PCG01UHZ01 | B12: BA SIMOES FILHO | C12: BA2 | D12: 89 | E12: 0.29166667
A13: LT0PCG01UBUI2 | B13: CRAVINHOS | C13: SP5 | D13: 94 | E13: 0.29166667
A14: LT0PCG01UBSY2 | B14: MG BETIM | C14: MG2 | D14: 91 | E14: 0.29166667
A15: LT0PCG01UBT03 | B15: MG BETIM | C15: MG2 | D15: 90 | E15: 0.29166667
A16: LT0PCG01UEB72 | B16: RJ DUQUE DE CAXIAS | C16: RJ2 | D16: NÃO DOCOU | E16: 0.29166667
A17: LT0PCG01UEB93 | B17: RJ DUQUE DE CAXIAS | C17: RJ2 | D17: 96 | E17: 0.29166667
A18: LT0PCG01U8OF1 | B18: RJ DUQUE DE CAXIAS | C18: RJ2 | D18: NÃO DOCOU | E18: 0.29166667
A19: LT0PCH01UJ011 | B19: JUNDIAI | C19: LSP-100 | D19: NÃO CHEGOU | E19: 0.29166667
A20: LT0PCH01UCMX1 | B20: PIRACICABA | C20: LSP-62 | D20: NÃO CHEGOU | E20: 0.29166667
A21: LT0PCH01UK3A1 | B21: BARUERI | C21: LSP-81 | D21: 9 | E21: 0.29166667
A22: LT0PCH01UD401 | B22: JURUBATUBA | C22: LSP-16 | D22: 15 | E22: 0.29166667
A23: LT0PCH01UD412 | B23: JURUBATUBA | C23: LSP-16 | D23: NÃO CHEGOU | E23: 0.29166667
A24: LT0PCH01UD5E1 | B24: PRAIA GRANDE 02 | C24: LSP-63 | D24: NÃO CHEGOU | E24: 0.29166667
A25: LT0PCH01U8HF1 | B25: MAUÁ | C25: LSP-64 | D25: 6 | E25: 0.29166667
A26: LT0PCG01UHYS1 | B26: BA SIMOES FILHO | C26: BA2 | D26: 88 | E26: 0.3125
A27: LT0PCH01UD4M1 | B27: GUARUJÁ | C27: LSP-06 | D27: NÃO CHEGOU | E27: 0.3125
A28: LT0PCH01UD4H1 | B28: ZIMBA | C28: LSP-74 | D28: NÃO CHEGOU | E28: 0.3125
A29: LT1PCH01UOU61 | B29: MOOCA | C29: LSP-13 | D29: 20 | E29: 0.3125
A30: LT0PCH01UBWE1 | B30: ITAPEVI | C30: LSP-41 | D30: 5 | E30: 0.3125
A31: LT0PCH01UD501 | B31: SÃO JOSÉ DOS CAMPOS | C31: LSP-04 | D31: 17 | E31: 0.3125

Sheet 1712
A1: LH | B1: DESTINO | C1: FANOUT | D1: DOCA | E1: CPT | G1: TOTAL DE CARROS EM CURSO PARA O T1 | H1: =SUM(H2,H3) -> 25
A2: LT1PCI01UQJI1 | B2: SC ITAJAI | C2: SC1 | D2: 26 | E2: 0.20833333 | G2: HUB | H2: 17
A3: LT0PCI01UBYL1 | B3: GUARATINGUETÁ | C3: LSP-33 | D3: 18 | E3: 0.25 | G3: SOCS | H3: 8
A4: LT0PCI01UBYA1 | B4: REGISTRO | C4: LSP-40 | D4: 14 | E4: 0.25
A5: LT0PCI01UCJ91 | B5: SÃO BERNARDO DO CAMPO | C5: LSP-79 | D5: 29 | E5: 0.25
A6: LT0PCI01UBZV1 | B6: VÁRZEA PAULISTA | C6: LSP-61 | D6: 45 | E6: 0.25 | G6: NÃO DOCADO | H6: 16
A7: LT0PCI01UHUH1 | B7: PE JABOATÃO DOS GUARARAPES | C7: PE2 | D7: 47 | E7: 0.25 | G7: MOTIVO: não havia chegado no pátio em tempo hábil SOCS DE CPT LONGO NÃO CHAMADOS PELA TELESCÓPICA
A8: LT0PCI01UBTD1 | B8: PR CURITIBA | C8: PR1 | D8: 9 | E8: 0.25 | G8: DESTINO: RJ2, BA2, GO2, SP5, MG2. LSP-13, LSP-87
A9: LT1PCI01UQAU1 | B9: PR CURITIBA | C9: PR1 | D9: 34 | E9: 0.25
A10: LT0PCI01UG6P1 | B10: ATIBAIA | C10: LSP-87 | D10: NÃO CHEGOU | E10: 0.27083333
A11: LT0PCI01U88C1 | B11: TAUBATÉ | C11: LSP-06 | D11: 8 | E11: 0.27083333
A12: LT0PCI01UD5K1 | B12: EMBU DAS ARTES | C12: LSP-36 | D12: 33 | E12: 0.27083333
A13: LT0PCI01UBUW1 | B13: LOUVEIRA | C13: SP7 | D13: 32 | E13: 0.29166667
A14: LT0PCH01UHZ11 | B14: BA SIMOES FILHO | C14: BA2 | D14: NÃO DOCOU | E14: 0.29166667
A15: LT1PCH01UPNJ1 | B15: BA SIMOES FILHO | C15: BA2 | D15: 48 | E15: 0.29166667
A16: LT1PCH01UQJC1 | B16: BA SIMOES FILHO | C16: BA2 | D16: NÃO DOCOU | E16: 0.29166667
A17: LT1PCH01UQJP1 | B17: GOIÂNIA 02 | C17: GO2 | D17: 87 | E17: 0.29166667
A18: LT0PCH01UHYZ2 | B18: BA SIMOES FILHO | C18: BA2 | D18: NÃO DOCOU | E18: 0.29166667
A19: LT0PCH01UI7B1 | B19: GOIÂNIA 02 | C19: GO2 | D19: NÃO DOCOU | E19: 0.29166667
A20: LT0PCH01UBUH2 | B20: CRAVINHOS | C20: SP5 | D20: NÃO DOCOU | E20: 0.29166667
A21: LT0PCH01UBSZ1 | B21: MG BETIM | C21: MG2 | D21: 49 | E21: 0.29166667
A22: LT0PCH01UBT12 | B22: MG BETIM | C22: MG2 | D22: NÃO DOCOU | E22: 0.29166667
A23: LT0PCH01UBT23 | B23: MG BETIM | C23: MG2 | D23: NÃO DOCOU | E23: 0.29166667
A24: LT0PCH01UBT34 | B24: MG BETIM | C24: MG2 | D24: NÃO DOCOU | E24: 0.29166667
A25: LT0PCH01UEB81 | B25: RJ DUQUE DE CAXIAS | C25: RJ2 | D25: NÃO DOCOU | E25: 0.29166667
A26: LT0PCH01UEBD4 | B26: RJ DUQUE DE CAXIAS | C26: RJ2 | D26: NÃO DOCOU | E26: 0.29166667
A27: LT0PCI01UHKS1 | B27: BARUERI | C27: LSP-81 | D27: 22 | E27: 0.29166667
A28: LT0PCI01UJ021 | B28: JUNDIAI | C28: LSP-100 | D28: 6 | E28: 0.29166667
A29: LT0PCI01UD3X1 | B29: JURUBATUBA | C29: LSP-16 | D29: 17 | E29: 0.29166667
A30: LT0PCI01UCMY1 | B30: PIRACICABA | C30: LSP-62 | D30: 27 | E30: 0.29166667
A31: LT0PCI01UD5A1 | B31: PRAIA GRANDE 02 | C31: LSP-63 | D31: 21 | E31: 0.29166667
A32: LT0PCI01UD5C2 | B32: PRAIA GRANDE 02 | C32: LSP-63 | D32: 25 | E32: 0.29166667
A33: LT0PCH01UI7D2 | B33: GOIÂNIA 02 | C33: GO2 | D33: 12 | E33: 0.29166667
A34: LT0PCI01UD4N1 | B34: GUARUJÁ | C34: LSP-06 | D34: 15 | E34: 0.3125
A35: LT0PCI01UD4I1 | B35: ZIMBA | C35: LSP-74 | D35: 36 | E35: 0.3125
A36: LT0PCI01UD4Z2 | B36: SÃO JOSÉ DOS CAMPOS | C36: LSP-04 | D36: 20 | E36: 0.3125
A37: LT0PCI01U8H41 | B37: MOOCA | C37: LSP-13 | D37: 7 | E37: 0.3125
A38: LT0PCI01U8H62 | B38: MOOCA | C38: LSP-13 | D38: NÃO CHEGOU | E38: 0.3125
A39: LT0PCI01UBWF1 | B39: ITAPEVI | C39: LSP-41 | D39: 5 | E39: 0.3125
A40: LT1PCH01UPNK1 | B40: BA SIMOES FILHO | C40: BA2 | D40: NÃO DOCOU | E40: 0.33333333
...

Sheet 1812
A1: LH | B1: DESTINO | C1: FANOUT | D1: DOCA | E1: CPT | G1: TOTAL DE CARROS EM CURSO PARA O T1 | H1: =SUM(H2,H3) -> 25
A2: LT0PCJ01UBYM1 | B2: GUARATINGUETÁ | C2: LSP-33 | D2: 41 | E2: 0.25 | G2: HUB | H2: 20
A3: LT0PCJ01UBZN1 | B3: LIMEIRA | C3: LSP-24 | D3: 39 | E3: 0.25 | G3: SOCS | H3: 5
A4: LT0PCJ01UBYB1 | B4: REGISTRO | C4: LSP-40 | D4: 17 | E4: 0.25
A5: LT0PCJ01UCJA1 | B5: SÃO BERNARDO DO CAMPO | C5: LSP-79 | D5: NÃO CHEGOU | E5: 0.25
A6: LT0PCJ01UBZW1 | B6: VÁRZEA PAULISTA | C6: LSP-61 | D6: 45 | E6: 0.25 | G6: NÃO DOCADO | H6: 13
A7: LT0PCJ01UHUI1 | B7: PE JABOATÃO DOS GUARARAPES | C7: PE2 | D7: 28 | E7: 0.25 | G7: MOTIVO: não havia chegado no pátio em tempo hábil SOCS DE CPT LONGO NÃO CHAMADOS PELA TELESCÓPICA
A8: LT0PCJ01UBTE1 | B8: PR CURITIBA | C8: PR1 | D8: 46 | E8: 0.25 | G8: DESTINO: RJ2, BA2, GO2, SP5, MG2. LSP-63, LSP-79, LSP-60 (APROVEITAMENTO DE SPR)
A9: LT0PCJ01U87H1 | B9: LOUVEIRA | C9: SP7 | D9: NÃO SE APRESENTOU | E9: 0.25
A10: LT0PCJ01UG6Q1 | B10: ATIBAIA | C10: LSP-87 | D10: 9 | E10: 0.27083333
A11: LT0PCJ01U88D1 | B11: TAUBATÉ | C11: LSP-08 | D11: 6 | E11: 0.27083333
A12: LT0PCJ01UD5L1 | B12: EMBU DAS ARTES | C12: LSP-36 | D12: 33 | E12: 0.27083333
A13: LT0PCI01UHYI1 | B13: BA SIMOES FILHO | C13: BA2 | E13: 0.29166667
A14: LT0PCI01UHZ21 | B14: BA SIMOES FILHO | C14: BA2 | D14: 89 | E14: 0.29166667
A15: LT1PCI01UR661 | B15: BA SIMOES FILHO | C15: BA2 | D15: 88 | E15: 0.29166667
A16: LT1PCI01UR6A1 | B16: GO GOIANIA 02 | C16: GO2 | D16: NÃO DOCOU/CPT ESTENDIDO | E16: 0.29166667
A17: LT1PCI01UR5V1 | B17: CRAVINHOS | C17: SP5 | D17: NÃO DOCOU/CPT ESTENDIDO | E17: 0.29166667
A18: LT0PCI01UI761 | B18: GO GOIANIA 02 | C18: GO2 | D18: NÃO DOCOU/CPT ESTENDIDO | E18: 0.29166667
A19: LT0PCI01UI782 | B19: GO GOIANIA 02 | C19: GO2 | D19: NÃO DOCOU/CPT ESTENDIDO | E19: 0.29166667
A20: LT0PCI01UBUJ1 | B20: SP CRAVINHOS | C20: SP5 | D20: NÃO DOCOU/CPT ESTENDIDO | E20: 0.29166667
A21: LT0PCJ01UHKU1 | B21: BARUERI | C21: LSP-81 | D21: 15 | E21: 0.29166667
A22: LT0PCJ01UJ031 | B22: JUNDIAI | C22: LSP-100 | D22: 12 | E22: 0.29166667
A23: LT0PCJ01UCMZ1 | B23: PIRACICABA | C23: LSP-62 | D23: 27 | E23: 0.29166667
A24: LT0PCJ01UD5D1 | B24: PRAIA GRANDE 02 | C24: LSP-63 | D24: 25 | E24: 0.29166667
A25: LT0PCJ01UD5F2 | B25: PRAIA GRANDE 02 | C25: LSP-63 | D25: 24 (NÃO CHEGOU) | E25: 0.29166667
A26: LT0PCJ01UD431 | B26: JURUBATUBA | C26: LSP-16 | D26: 18 | E26: 0.29166667
A27: LT0PCJ01UD452 | B27: JURUBATUBA | C27: LSP-16 | D27: 13 | E27: 0.29166667
A28: LT0PCJ01U8HH1 | B28: MAUÁ | C28: LSP-64 | D28: 14 | E28: 0.29166667
A29: LT1PCI01UR6A1 | B29: GO GOIANIA 02 | C29: GO2 | D29: 100 | E29: 0.29166667
A30: LT0PCJ01UD4O1 | B30: GUARUJÁ | C30: LSP-06 | D30: 8 | E30: 0.3125
A31: LT0PCJ01UD4J1 | B31: ZIMBA | C31: LSP-74 | D31: 29 | E31: 0.3125
A32: LT0PCJ01UD4U1 | B32: PRAIA GRANDE | C32: LSP-09 | D32: 32 | E32: 0.3125
A33: LT0PCJ01UD511 | B33: SÃO JOSÉ DOS CAMPOS | C33: LSP-04 | D33: 21 | E33: 0.3125
A34: LT0PCJ01UBWG1 | B34: ITAPEVI | C34: LSP-41 | D34: 5 | E34: 0.3125
A35: LT0PCJ01U8H81 | B35: MOOCA | C35: LSP-13 | D35: 7 | E35: 0.3125
A36: LT1PCI01UR671 | B36: BA SIMOES FILHO | C36: BA2 | D36: NÃO DOCOU/CPT ESTENDIDO | E36: 0.33333333
A37: LT1PCI01UR6B1 | B37: GO GOIANIA 02 | C37: GO2 | D37: NÃO DOCOU/CPT ESTENDIDO | E37: 0.33333333
A38: LT1PCI01UR621 | B38: MG BETIM | C38: MG2 | D38: NÃO DOCOU/CPT ESTENDIDO | E38: 0.33333333
A39: LT1PCI01UR5W1 | B39: SP CRAVINHOS | C39: SP5 | D39: NÃO DOCOU/CPT ESTENDIDO | E39: 0.33333333
A40: LT1PCI01UR601 | B40: RJ DUQUE DE CAXIAS | C40: RJ2 | D40: NÃO DOCOU/CPT ESTENDIDO | E40: 0.33333333
...

Sheet 1912
A1: LH | B1: DESTINO | C1: FANOUT | D1: DOCA | E1: CPT | G1: TOTAL DE CARROS EM CURSO PARA O T1 | H1: =SUM(H2,H3) -> 12
A2: LT0PCK01U88E1 | B2: TAUBATÉ | C2: LSP-08 | D2: 8 | E2: 0.27083333 | G2: HUB | H2: 10
A3: LT0PCK01UD5M1 | B3: EMBU DAS ARTES | C3: LSP-36 | D3: 32 | E3: 0.27083333 | G3: SOCS | H3: 2
A4: LT0PCJ01UI771 | B4: GOIÂNIA 02 | C4: GO2 | D4: NÃO DOCOU | E4: 0.29166667
A5: LT0PCJ01UBUK1 | B5: CRAVINHOS | C5: SP5 | D5: 36 | E5: 0.29166667
A6: LT0PCK01UHKV1 | B6: BARUERI | C6: LSP-81 | D6: 13 | E6: 0.29166667 | G6: NÃO DOCADO | H6: 4
A7: LT0PCK01UJ041 | B7: JUNDIAI | C7: LSP-100 | D7: 7 | E7: 0.29166667 | G7: MOTIVO: HUB'S não havia chegado no pátio em tempo hábil SOCS DE CPT LONGO NÃO CHAMADOS PELA TELESCÓPICA
A8: LT0PCK01UD3Y1 | B8: JURUBATUBA | C8: LSP-16 | D8: 19 | E8: 0.29166667 | G8: DESTINO: GO2, LSP-06, LSP-13, BA2
A9: LT0PCK01UCN01 | B9: PIRACICABA | C9: LSP-62 | D9: 17 | E9: 0.3125
A10: LT0PCK01UD4P1 | B10: GUARUJÁ | C10: LSP-06 | D10: 33 (NÃO CHEGOU) | E10: 0.3125
A11: LT0PCK01UD4K1 | B11: ZIMBA | C11: LSP-74 | D11: 5 | E11: 0.3125
A12: LT0PCK01UBWH1 | B12: ITAPEVI | C12: LSP-41 | D12: 42 | E12: 0.3125
A13: LT0PCK01UD4V1 | B13: PRAIA GRANDE | C13: LSP-09 | D13: 18 | E13: 0.3125
A14: LT0PCK01UD521 | B14: SÃO JOSÉ DOS CAMPOS | C14: LSP-04 | D14: 15 | E14: 0.3125
A15: LT0PCK01U8H91 | B15: MOOCA | C15: LSP-13 | D15: 14 (NÃO CHEGOU) | E15: 0.3125
A16: LT0PCK01UGWT1 | B16: ITAJAI | C16: SC1 | D16: 25 | E16: 0.20833333
A17: LT1PCJ01V15L1 | B17: BA SIMOES FILHO | C17: BA2 | D17: NÃO DOCOU | E17: 0.20833333

Sheet 2212
A1: LH | B1: DESTINO | C1: FANOUT | D1: DOCA | E1: CPT | G1: TOTAL DE CARROS EM CURSO PARA O T1 | H1: =SUM(H2,H3) -> 23
A2: LT0PCN01UVPP1 | B2: GUARATINGUETÁ | C2: LSP-33 | D2: 36 | E2: 0.25 | G2: HUB | H2: 14
A3: LT0PCN01UVQG1 | B3: LIMEIRA | C3: LSP-24 | D3: 7 | E3: 0.25 | G3: SOCS | H3: 9
A4: LT0PCN01UVPI1 | B4: REGISTRO | C4: LSP-40 | D4: 9 | E4: 0.25
A5: LT0PCN01UVQN1 | B5: VÁRZEA PAULISTA | C5: LSP-61 | D5: 8 | E5: 0.25
A6: LT0PCN01UVM81 | B6: CURITIBA | C6: PR1 | D6: 42 | E6: 0.25 | G6: NÃO DOCADO | H6: 8
A7: LT0PCN01UY6N1 | B7: ATIBAIA | C7: LSP-87 | D7: 35 | E7: 0.27083333 | G7: DESTINO: GO2, LSP-08, LSP-63, BA2, LSP-04, LSP-09,LSP-41, LSP-16
A8: LT0PCN01UWF41 | B8: EMBU DAS ARTES | C8: LSP-36 | D8: 33 | E8: 0.27083333
A9: LT0PCN01UVPX1 | B9: TAUBATÉ | C9: LSP-08 | D9: NÃO CHEGOU | E9: 0.27083333
A10: LT0PCM01UZJ11 | B10: GOIÂNIA | C10: GO2 | D10: 87 | E10: 0.29166667
A11: LT0PCM01UZJ32 | B11: GOIÂNIA | C11: GO2 | D11: NÃO DOCOU | E11: 0.29166667
A12: LT0PCM01UZKB1 | B12: GRAVATAI | C12: RS2 | D12: 14 | E12: 0.29166667
A13: LT0PCM01UYNN1 | B13: ITAJAI | C13: SC1 | D13: 15 | E13: 0.29166667
A14: LT0PCM01UVMX1 | B14: SP CRAVINHOS | C14: SP5 | D14: 94 | E14: 0.29166667
A15: LT0PCM01UTBR1 | B15: MG BETIM | C15: MG2 | D15: 91 | E15: 0.29166667
A16: LT0PCM01UX3F1 | B16: RJ DUQUE DE CAXIAS | C16: RJ2 | D16: 97 | E16: 0.29166667
A17: LT0PCN01UU001 | B17: BARUERI | C17: LSP-81 | D17: 18 | E17: 0.29166667
A18: LT0PCN01V0141 | B18: JUNDIAI | C18: LSP-100 | D18: 5 | E18: 0.29166667
A19: LT0PCN01UW4R1 | B19: PIRACICABA | C19: LSP-62 | D19: 39 | E19: 0.29166667
A20: LT0PCN01UWF11 | B20: PRAIA GRANDE 02 | C20: LSP-63 | D20: NÃO CHEGOU | E20: 0.29166667
A21: LT0PCN01UWE91 | B21: JURUBATUBA | C21: LSP-16 | D21: 16 (NÃO CHEGOU) | E21: 0.29166667
A22: LT0PCN01UWEN1 | B22: GUARUJÁ | C22: LSP-06 | D22: 37 | E22: 0.3125
A23: LT0PCN01UTC91 | B23: ITAPEVI | C23: LSP-41 | D23: NÃO CHEGOU | E23: 0.3125
A24: LT0PCN01UWEK1 | B24: ZIMBA | C24: LSP-74 | D24: 21 | E24: 0.3125
A25: LT0PCN01UWEQ1 | B25: PRAIA GRANDE | C25: LSP-09 | D25: NÃO CHEGOU | E25: 0.3125
A26: LT0PCN01UWET1 | B26: SÃO JOSÉ DOS CAMPOS | C26: LSP-04 | D26: 17 (NÃO SE APRESENTOU) | E26: 0.3125
A27: LT0PCN01V0911 | B27: SUZANO | C27: LSP-97 | D27: 4 | E27: 0.3125
A28: LT0PCN01UTHC1 | B28: MOOCA | C28: LSP-13 | D28: 25 | E28: 0.3125
A29: LT0PCN01UVQA2 | B29: SOROCABA | C29: LSP-10 | D29: 6 | E29: 0.22916667
A30: LT1PCM01V6B31 | B30: BA SIMOES FILHO | C30: BA2 | D30: 114 | E30: 0.041666667
A31: LT0PCN01UVA61 | B31: SP CRAVINHOS | C31: SP5 | D31: 112 | E31: 0.10416667
A32: LT1PCN01VNN81 | B32: BA SIMOES FILHO | C32: BA2 | D32: NÃO DOCOU | E32: 0.125
A33: LT1PCN01V6B41 | B33: BA SIMOES FILHO | C33: BA2 | D33: NÃO DOCOU | E33: 0.20833333

Sheet 2312
A1: LH | B1: DESTINO | C1: FANOUT | D1: DOCA | E1: CPT | G1: TOTAL DE CARROS EM CURSO PARA O T1 | H1: =SUM(H2,H3) -> 21
A2: LT0PCO01UVPJ1 | B2: REGISTRO | C2: LSP-40 | D2: 9 | E2: 0.25 | G2: HUB | H2: 11
A3: LT0PCO01UVQH1 | B3: LIMEIRA | C3: LSP-24 | D3: 13 | E3: 0.25 | G3: SOCS | H3: 10
A4: LT0PCO01UW2E1 | B4: SÃO BERNARDO DO CAMPO | C4: LSP-79 | D4: 15 | E4: 0.25
A5: LT0PCO01UY6O1 | B5: ATIBAIA | C5: LSP-87 | D5: 34 | E5: 0.25
A6: LT0PCO01UWF51 | B6: EMBU DAS ARTES | C6: LSP-36 | D6: 22 | E6: 0.25 | G6: NÃO DOCADO | H6: 3
A7: LT0PCO01V0151 | B7: JUNDIAI | C7: LSP-100 | D7: 8 | E7: 0.27083333 | G7: DESTINO: LSP-09, PR1, LSP-97
A8: LT0PCO01UW4T1 | B8: PIRACICABA | C8: LSP-62 | D8: 27 | E8: 0.27083333
A9: LT0PCO01UWF21 | B9: PRAIA GRANDE 02 | C9: LSP-63 | D9: 24 | E9: 0.27083333
A10: LT0PCO01UWEB1 | B10: JURUBATUBA | C10: LSP-16 | D10: NO SHOW | E10: 0.29166667
A11: LT0PCO01UZ3T1 | B11: BARUERI | C11: LSP-81 | D11: 17 | E11: 0.29166667
A12: LT0PCO01UWEL1 | B12: ZIMBA | C12: LSP-74 | D12: 12 | E12: 0.29166667
A13: LT0PCO01UWEO1 | B13: GUARUJÁ | C13: LSP-06 | D13: 33 | E13: 0.29166667
A14: LT0PCO01UWER1 | B14: PRAIA GRANDE | C14: LSP-09 | D14: NÃO CHEGOU | E14: 0.29166667
A15: LT0PCO01V0921 | B15: SUZANO BARUEL | C15: LSP-97 | D15: NÃO CHEGOU | E15: 0.29166667
B16: GOIANIA 02 | C16: GO2 | D16: 114 | E16: 0.29166667
B17: GOIANIA 02 | C17: GO2 | D17: 113 | E17: 0.29166667
A18: LT0PCN01UZIM1 | B18: GOIANIA 02 | C18: GO2 | D18: 86 | E18: 0.29166667
A19: LT1PCN01VNPB1 | B19: SP CRAVINHOS | C19: SP5 | D19: 94 | E19: 0.29166667
A20: LT1PCN01VNQ01 | B20: JABOATÃO DOS GUARARAPES | C20: PE2 | D20: 99 | E20: 0.29166667
A21: LT0PCN01UYNM2 | B21: ITAJAI | C21: SC1 | D21: 21 | E21: 0.29166667
A22: LT0PCN01UYNL1 | B22: ITAJAI | C22: SC1 | D22: 100 | E22: 0.3125
A23: LT0PCO01UVM71 | B23: CURITIBA | C23: PR1 | D23: NÃO DOCOU | E23: 0.3125
A24: LT0PCN01UTLW1 | B24: RJ DUQUE DE CAXIAS | C24: RJ2 | D24: 96 | E24: 0.3125
A25: LT1PCN01VOL51 | B25: SIMOES FILHO | C25: BA2 | D25: 89 | E25: 0.3125
A26: LT0PCO01UVZ61 | B26: SP SANTANA | C26: SP2 | D26: 32 | E26: 0.3125

Sheet 2612
A1: LH | B1: DESTINO | C1: FANOUT | D1: DOCA | E1: CPT | G1: TOTAL DE CARROS EM CURSO PARA O T1 | H1: =SUM(H2,H3) -> 26
A2: LT1PCQ01VTXP1 | B2: SP CRAVINHOS | C2: SP5 | D2: 95 | E2: 0.083333333 | G2: HUB | H2: 11
A3: LT1PCR01VTOM1 | B3: ITAJAI | C3: SC1 | D3: 5 | E3: 0.125 | G3: SOCS | H3: 15
A4: LT1PCR01VTP71 | B4: BA SIMOES FILHO | C4: BA2 | D4: 111 | E4: 0.16666667
A5: LT1PCR01VTOV1 | B5: RJ DUQUE DE CAXIAS | C5: RJ2 | D5: 110 | E5: 0.16666667
A6: LT0PCR01UVQ91 | B6: SOROCABA | C6: LSP-10 | D6: 25 | E6: 0.22916667
A7: LT1PCR01VV3A1 | B7: MG BETIM | C7: MG2 | D7: 91 | E7: 0.25 | G7: NÃO DOCADO | H7: 13
A8: LT0PCR01UVM91 | B8: PR CURITIBA | C8: PR1 | D8: 6 | E8: 0.25 | G8: DESTINO: LSP-79, LSP-61, LSP-08, MG2, PE2, GO2, LSP-16, LSP-62, LSP-63, SP2, LSP-09, LSP-13
A9: LT0PCR01UY6P1 | B9: ATIBAIA | C9: LSP-87 | D9: 14 | E9: 0.27083333 | G9: MOTIVO: LSP-79 e 61 estavam aguardando descarga no HUB. LSP-08 motorista foi embora MG2 não chegou no horário assim como os demais fanouts PE2 e GO2 não foram chamados para docar devido volumetria das telescópicas
A10: LT0PCR01UWF61 | B10: EMBU DAS ARTES | C10: LSP-36 | D10: 9 | E10: 0.27083333
A11: LT0PCQ01UZC71 | B11: BA SIMOES FILHO | C11: BA2 | D11: 89 | E11: 0.29166667
A12: LT0PCQ01UZC92 | B12: BA SIMOES FILHO | C12: BA2 | D12: 88 | E12: 0.29166667
A13: LT0PCQ01UZA82 | B13: PE JABOATÃO DOS GUARARAPES | C13: PE2 | D13: 98 | E13: 0.29166667
A14: LT0PCQ01UTM02 | B14: RJ DUQUE DE CAXIAS | C14: RJ2 | D14: 97 | E14: 0.29166667
A15: LT0PCQ01UYNO1 | B15: SC ITAJAI | C15: SC1 | D15: 100 | E15: 0.29166667
A16: LT0PCQ01UZKE1 | B16: RS GRAVATAI 02 | C16: RS2 | D16: 17 | E16: 0.29166667
A17: LT0PCQ01UZKG2 | B17: RS GRAVATAI 02 | C17: RS2 | D17: 102 | E17: 0.29166667
A18: LT0PCQ01UZJ01 | B18: GOIANIA 02 | C18: GO2 | D18: 87 | E18: 0.29166667
A19: LT0PCR01V0161 | B19: JUNDIAI | C19: LSP-100 | D19: 36 | E19: 0.29166667
A20: LT0PCQ01UTLY1 | B20: RJ DUQUE DE CAXIAS | C20: RJ2 | D20: 112 | E20: 0.29166667
A21: LT0PCR01UZ3U1 | B21: BARUERI | C21: LSP-81 | D21: 19 | E21: 0.29166667
... A27: LT0PCR01UVOA1 | B27: ITAPEVI | C27: LSP-41 | D27: 8 | E27: 0.3125
A28: LT0PCR01UW2F1 | B28: SÃO BERNARDO DO CAMPO | C28: LSP-79 | D28: NÃO DOCOU | E28: 0.25
A29: LT0PCR01UVQP1 | B29: VÁRZEA PAULISTA | C29: LSP-61 | D29: NÃO DOCOU | E29: 0.25
A30: LT0PCR01UVPY1 | B30: TAUBATÉ | C30: LSP-08 | D30: MOTORISTA FOI EMBORA | E30: 0.25
A31: LT0PCQ01UVM32 | B31: MG BETIM | C31: MG2 | D31: NÃO CHEGOU NO HORÁRIO | E31: 0.29166667
A32: LT0PCQ01UZAA3 | B32: PE JABOATÃO DOS GUARARAPES | C32: PE2 | D32: NÃO DOCOU | E32: 0.29166667
A33: LT0PCQ01UZJ22 | B33: GOIANIA 02 | C33: GO2 | D33: NÃO DOCOU | E33: 0.29166667
A34: LT0PCR01UWE81 | B34: JURUBATUBA | C34: LSP-16 | D34: NÃO CHEGOU NO HORÁRIO | E34: 0.29166667
A35: LT0PCR01UWEA2 | B35: JURUBATUBA | C35: LSP-16 | D35: NÃO CHEGOU NO HORÁRIO | E35: 0.29166667
A36: LT0PCR01UW4U1 | B36: PIRACICABA | C36: LSP-62 | D36: NÃO CHEGOU NO HORÁRIO | E36: 0.29166667
A37: LT0PCR01UWF31 | B37: PRAIA GRANDE 02 | C37: LSP-63 | D37: NÃO CHEGOU NO HORÁRIO | E37: 0.29166667
A38: LT0PCR01UVZ71 | B38: SP SANTANA | C38: SP2 | D38: NÃO CHEGOU NO HORÁRIO | E38: 0.29166667
A39: LT0PCR01UWES1 | B39: PRAIA GRANDE | C39: LSP-09 | D39: NÃO CHEGOU NO HORÁRIO | E39: 0.3125
... A41: LT0PCR01UTHB1 | B41: MOOCA | C41: LSP-13 | D41: NÃO CHEGOU NO HORÁRIO | E41: 0.3125

Sheet 2912
A1: LH | B1: DESTINO | C1: FANOUT | D1: DOCA | E1: CPT | G1: TOTAL DE CARROS EM CURSO PARA O T1 | H1: =SUM(H2,H3) -> 28
A2: LT1PCT01VX0L1 | B2: BA SIMOES FILHO | C2: BA2 | D2: 89 | E2: 0.95833333 | G2: HUB | H2: 20
A3: LT0PCU01V8351 | B3: GUARATINGUETÁ | C3: LSP-33 | D3: 7 | E3: 0.25 | G3: SOCS | H3: 8
A4: LT0PCU01V83Y1 | B4: LIMEIRA | C4: LSP-24 | D4: 12 | E4: 0.25
A5: LT0PCU01V82Y1 | B5: REGISTRO | C5: LSP-40 | D5: 15 | E5: 0.25
A6: LT0PCU01V9HT2 | B6: RJ DUQUE DE CAXIAS | C6: RJ2 | D6: 97 | E6: 0.25
A7: LT0PCU01V8G21 | B7: SÃO BERNARDO DO CAMPO | C7: LSP-79 | D7: 27 | E7: 0.25
A8: LT0PCU01V8451 | B8: VÁRZEA PAULISTA | C8: LSP-61 | D8: 13 | E8: 0.25
A9: LT1PCU01VX0F1 | B9: PE JABOATÃO DOS GUARARAPES | C9: PE2 | D9: 98 | E9: 0.25 | G9: NÃO DOCADO
A10: LT0PCU01V7ZF1 | B10: CURITIBA | C10: PR1 | D10: 21 | E10: 0.25 | G10: DESTINO:
A11: LT0PCU01VAMC1 | B11: ATIBAIA | C11: LSP-87 | D11: 26 | E11: 0.27083333 | G11: MOTIVO:
A12: LT0PCU01V8SW1 | B12: EMBU DAS ARTES | C12: LSP-36 | D12: 5 | E12: 0.27083333
A13: LT0PCU01VQ3D1 | B13: TAUBATÉ | C13: LSP-08 | D13: 16 | E13: 0.27083333
A14: LT0PCT01VBZF1 | B14: GOIÂNIA 02 | C14: GO2 | D14: 87/86 | E14: 0.29166667
A15: LT0PCT01VB421 | B15: SC ITAJAI | C15: SC1 | D15: 100 | E15: 0.29166667
A16: LT0PCT01V8051 | B16: SP CRAVINHOS | C16: SP5 | D16: 94 | E16: 0.29166667
A17: LT0PCT01VC0Q1 | B17: RS GRAVATAI | C17: RS2 | D17: 102 | E17: 0.29166667
A18: LT0PCU01VBJQ1 | B18: BARUERI | C18: LSP-81 | D18: 18 | E18: 0.29166667
A19: LT0PCU01VCH91 | B19: JUNDIAI | C19: LSP-100 | D19: 35 | E19: 0.29166667
A20: LT0PCU01V8I11 | B20: PIRACICABA | C20: LSP-62 | D20: 37 | E20: 0.29166667
A21: LT0PCU01V8ST1 | B21: PRAIA GRANDE 02 | C21: LSP-63 | D21: 23 | E21: 0.29166667
A22: LT0PCU01V8S11 | B22: JURUBATUBA | C22: LSP-16 | D22: 39 | E22: 0.29166667
A23: LT0PCU01V8SF1 | B23: GUARUJÁ | C23: LSP-06 | D23: 34 | E23: 0.3125
A24: LT0PCU01V81L1 | B24: ITAPEVI | C24: LSP-41 | D24: 15 | E24: 0.3125
A25: LT0PCU01V8SC1 | B25: ZIMBA | C25: LSP-74 | D25: 22 | E25: 0.3125
A26: LT0PCU01V8SI1 | B26: PRAIA GRANDE | C26: LSP-09 | D26: 9 | E26: 0.3125
... A29: LT0PCU01VQCZ1 | B29: MOOCA | C29: LSP-13 | D29: 49 | E29: 0.3125

Sheet 3012
A1: LH | B1: DESTINO | C1: FANOUT | D1: DOCA | E1: CPT | G1: TOTAL DE CARROS EM CURSO PARA O T1 | H1: =SUM(H2,H3) -> 12
A2: LT0PCV01V8SX1 | B2: EMBU DAS ARTES | C2: LSP-36 | D2: 15 | E2: 0.27083333 | G2: HUB | H2: 9
A3: LT0PCV01VAMD1 | B3: ATIBAIA | C3: LSP-87 | D3: 34 | E3: 0.27083333 | G3: SOCS | H3: 3
A4: LT0PCV01V8I31 | B4: PIRACICABA | C4: LSP-64 | D4: NÃO CHEGOU | E4: 0.29166667
A5: LT0PCV01VBJR1 | B5: BARUERI | C5: LSP-81 | D5: 18 | E5: 0.29166667
A6: LT0PCV01VCHA1 | B6: JUNDIAI | C6: LSP-100 | D6: 36 | E6: 0.29166667
A7: LT0PCV01V8SD1 | B7: ZIMBA | C7: LSP-74 | D7: NÃO CHEGOU | E7: 0.3125
A8: LT0PCV01V8SJ1 | B8: PRAIA GRANDE | C8: LSP-09 | D8: 7 | E8: 0.3125
A9: LT0PCV01V81N1 | B9: ITAPEVI | C9: LSP-41 | D9: 14 | E9: 0.3125 | G9: NÃO DOCADO | H9: 2
A10: LT0PCV01V8SG1 | B10: GUARUJÁ | C10: LSP-06 | D10: 33 | E10: 0.3125 | G10: DESTINO: LSP-64, LSP-74
A11: LT0PCV01VAHA1 | B11: EMBU DAS ARTES 02 | C11: LSP-96 | D11: 16 | E11: 0.33333333 | G11: MOTIVO: NÃO CHEGARAM NO PRAZO DA ETA
A12: LT0PCV01V8MY1 | B12: PARQUE NOVO MUNDO | C12: LSP-89 | D12: EXPEDIDO | E12: 0.35416667
A13: LT0PCV01V8S41 | B13: CARANDIRU | C13: LSP-18 | D13: 37 | E13: 0.375
A14: LT0PCU01VQKI1 | B14: RJ DUQUE DE CAXIAS | C14: RJ2 | D14: 96 | E14: 0.125
A15: LT0PCU01VB432 | B15: ITAJAI | C15: SC1 | D15: 100 | E15: 0.75
A16: LT0PCU01VBZD3 | B16: GOIANIA 02 | C16: GO2 | D16: 87 | E16: 0.95833333

Sheet 0201
A1: LH | B1: DESTINO | C1: FANOUT | D1: DOCA | E1: CPT | G1: TOTAL DE CARROS EM CURSO PARA O T1 | H1: =SUM(H2,H3) -> 25
A2: LT0Q1301V8SY1 | B2: EMBU DAS ARTES | C2: LSP-36 | D2: 44 | E2: 0.27083333 | G2: HUB | H2: 15
A3: LT0Q1301VQ3G1 | B3: TAUBATÉ | C3: LSP-08 | D3: 19 | E3: 0.27083333 | G3: SOCS | H3: 10
A4: LT0Q1301VAME1 | B4: ATIBAIA | C4: LSP-87 | D4: 9 | E4: 0.27083333
A5: LT0Q1201V7ZB2 | B5: MG BETIM | C5: MG2 | D5: 91 | E5: 0.29166667
A6: LT0Q1201VB441 | B6: SC ITAJAI | C6: SC1 | D6: 100 | E6: 0.29166667
A7: LT0Q1201VBQD2 | B7: PE JABOATÃO | C7: PE2 | D7: NÃO DOCOU | E7: 0.29166667
A8: LT0Q1201VBQF3 | B8: PE JABOATÃO | C8: PE2 | D8: NÃO DOCOU | E8: 0.29166667
A9: LT0Q1201VBSD1 | B9: BA SIMOES FILHO | C9: BA2 | D9: NÃO DOCOU | E9: 0.29166667 | G9: NÃO DOCADO | H9: 13
A10: LT0Q1201VBSF2 | B10: BA SIMOES FILHO | C10: BA2 | D10: NÃO DOCOU | E10: 0.29166667 | G10: DESTINO: LSP-62, LSP-16, LSP-81, LSP-74, LSP-97 PE2, BA2, GO2, PR1
A11: LT0Q1201VBSH3 | B11: BA SIMOES FILHO | C11: BA2 | D11: NÃO DOCOU | E11: 0.29166667 | G11: MOTIVO: HUBS NÃO CHEGARAM NO PRAZO DA ETA SOC's EXCETO PR1 QUE NÃO CHEGOU NO ETA, NÃO DOCARAM POR FALTA DE PISO
A12: LT0Q1201VBZG1 | B12: GOIANIA 02 | C12: GO2 | D12: NÃO DOCOU | E12: 0.29166667
A13: LT0Q1201VBZI2 | B13: GOIANIA 02 | C13: GO2 | D13: NÃO DOCOU | E13: 0.29166667
A14: LT0Q1201VC0R2 | B14: RS GRAVATAI | C14: RS2 | D14: 102 | E14: 0.29166667
A15: LT0Q1201VQKM1 | B15: SC ITAJAI | C15: SC1 | D15: 100 | E15: 0.29166667
A16: LT0Q1201V9I21 | B16: GOIANIA 02 | C16: GO2 | D16: 87 | E16: 0.29166667
A17: LT0Q1301V8I41 | B17: PIRACICABA | C17: LSP-62 | D17: NÃO CHEGOU | E17: 0.29166667
A18: LT0Q1301V8S01 | B18: JURUBATUBA | C18: LSP-16 | D18: 33 | E18: 0.29166667
A19: LT0Q1301V8S22 | B19: JURUBATUBA | C19: LSP-16 | D19: NÃO CHEGOU | E19: 0.29166667
A20: LT0Q1301V8SV1 | B20: PRAIA GRANDE 02 | C20: LSP-63 | D20: 28 | E20: 0.29166667
A21: LT0Q1301VCHB1 | B21: JUNDIAI | C21: LSP-100 | D21: 34 | E21: 0.29166667
A22: LT0Q1301VBJU1 | B22: BARUERI | C22: LSP-81 | D22: NÃO CHEGOU | E22: 0.29166667
A23: LT0Q1301VQDL1 | B23: MAUÁ | C23: LSP-64 | D23: 18 | E23: 0.29166667
A24: LT0Q1301V81O1 | B24: ITAPEVI | C24: LSP-41 | D24: 36 | E24: 0.3125
A25: LT0Q1301V8SE1 | B25: ZIMBA | C25: LSP-74 | D25: NÃO CHEGOU | E25: 0.3125
A26: LT0Q1301V8SH1 | B26: GUARUJÁ | C26: LSP-06 | D26: 37 | E26: 0.3125
A27: LT0Q1301V8SK1 | B27: PRAIA GRANDE | C27: LSP-09 | D27: 32 | E27: 0.3125
A28: LT0Q1301VCQS1 | B28: SUZANO BARUEL | C28: LSP-97 | D28: NÃO CHEGOU | E28: 0.3125
A29: LT0Q1301V8SM1 | B29: SÃO JOSÉ DOS CAMPOS | C29: LSP-04 | D29: 18 | E29: 0.3125
A30: LT0Q1301VQD22 | B30: MOOCA | C30: LSP-13 | D30: 34 | E30: 0.3125
A31: LT0Q1301V7ZG1 | B31: PR CURITIBA | C31: PR1 | D31: NÃO CHEGOU | E31: 0.3125
A32: LT0Q1301V8CT1 | B32: SANTANA | C32: SP2 | D32: 15 | E32: 0.33333333
A33: LT0Q1301V8SB1 | B33: VILA GUILHERME | C33: LSP-68 | D33: 43 | E33: 0.33333333
A34: LT0Q1301VAHB1 | B34: EMBU DAS ARTES 02 | C34: LSP-96 | D34: 12 | E34: 0.33333333
A35: LT0Q1301V8RW1 | B35: JARDIM ADRIANA | C35: LSP-12 | D35: 5 | E35: 0.33333333
A36: LT0Q1201VBSB2 | B36: BA SIMOES FILHO | C36: BA2 | D36: 88 | E36: 0.95833333
A37: LT0Q1201VBQ51 | B37: PE JABOATÃO | C37: PE2 | D37: 17 | E37: 0.95833333
A38: LT0Q1201VBQ82 | B38: PE JABOATÃO | C38: PE2 | D38: 98 | E38: 0.95833333
A39: LT1Q1201VYEU1 | B39: RJ DUQUE DE CAXIAS | C39: RJ2 | D39: 110 | E39: 0

Sheet 0501
A1: LH | B1: DESTINO | C1: FANOUT | D1: DOCA | E1: CPT | G1: TOTAL DE CARROS EM CURSO PARA O T1 | H1: =SUM(H2,H3) -> 24
A2: LT1Q1501W2LH1 | B2: SP CRAVINHOS | C2: SP5 | D2: 94 | E2: 0.16666667 | G2: HUB | H2: 9
A3: LT1Q1601W2IK1 | B3: PE JABOATÃO DOS GUARARAPES | C3: PE2 | D3: 21 | E3: 0.20833333 | G3: SOCS | H3: 15
A4: LT0Q1601VFLD1 | B4: SOROCABA | C4: LSP-10 | D4: 4 | E4: 0.22916667
A5: LT0Q1601VFFI1 | B5: PR CURITIBA | C5: PR1 | D5: 114 | E5: 0.25
A6: LT0Q1601VFM21 | B6: VÁRZEA PAULISTA | C6: LSP-61 | D6: 7 | E6: 0.25
A7: LT0Q1601VFKK1 | B7: GUARATINGUETÁ | C7: LSP-33 | D7: 20 | E7: 0.25
A8: LT0Q1601VGO41 | B8: EMBU DAS ARTES | C8: LSP-36 | D8: 14 | E8: 0.27083333
A9: LT0Q1601VFKV1 | B9: TAUBATÉ | C9: LSP-08 | D9: 15 | E9: 0.27083333
A10: LT0Q1601VFZT1 | B10: SP SANTANA | C10: SP2 | D10: 8 | E10: 0.29166667 | G10: NÃO DOCADO | H10: 4
A11: LT0Q1601VRF81 | B11: MAUÁ | C11: LSP-64 | D11: 18 | E11: 0.29166667 | G11: DESTINO: LSP-62, LSP-74, SC1, BA2
A12: LT0Q1601VMD51 | B12: JUNDIAI | C12: LSP-100 | D12: 35 | E12: 0.29166667 | G12: MOTIVO: HUBS NÃO CHEGARAM NO PRAZO DA ETA SOC's NÃO DOCARAM POR FALTA DE PISO
A13: LT0Q1501VK9I1 | B13: SC ITAJAI | C13: SC1 | D13: 100 | E13: 0.29166667
A14: LT0Q1501VLAB1 | B14: BA SIMOES FILHOS | C14: BA2 | D14: 88 | E14: 0.29166667
A15: LT0Q1501VHRQ1 | B15: RJ DUQUE DE CAXIAS | C15: RJ2 | D15: 98 | E15: 0.29166667
A16: LT0Q1501VL6T1 | B16: PE JABOATÃO DOS GUARARAPES | C16: PE2 | D16: 99 | E16: 0.29166667
A17: LT0Q1501VLMD1 | B17: RS GRAVATAI | C17: RS2 | D17: 102 | E17: 0.29166667
A18: LT0Q1601VGNI1 | B18: PRAIA GRANDE | C18: LSP-09 | D18: 9 | E18: 0.29166667
A19: LT0Q1601VI9H1 | B19: SANTO ANDRÉ | C19: LSP-93 | D19: 19 | E19: 0.375
A20: LT1Q1601W2IQ1 | B20: RS GRAVATAI | C20: RS2 | D20: 112 | E20: 0.375
A21: LT0Q1601VGGM1 | B21: GUARULHOS | C21: SP6 | D21: 17 | E21: 0.375
A22: LT0Q1501VQYI1 | B22: MG BETIM | C22: MG2 | D22: 91 | E22: 0.375
A23: LT0Q1601VFG21 | B23: SP CRAVINHOS | C23: SP5 | D23: 94 | E23: 0.5
A24: LT0Q1601VK941 | B24: SC ITAJAI | C24: SC1 | D24: NÃO DOCOU | E24: 0.66666667
A25: LT0Q1601VL9R1 | B25: BA SIMOES FILHOS | C25: BA2 | D25: NÃO DOCOU | E25: 0.66666667
A26: LT0Q1601VRQN1 | B26: RJ DUQUE DE CAXIAS | C26: RJ2 | D26: 113 | E26: 0.66666667
A27: LT0Q1601VLJS1 | B27: GO GOIANIA | C27: GO2 | D27: 87 | E27: 0.66666667
A28: LT0Q1601VG7M1 | B28: PIRACICABA | C28: LSP-62 | D28: PREVISÃO DE CHEGADA 06:30 | E28: 0.29166667
A29: LT0Q1601VGN81 | B29: ZIMBA | C29: LSP-74 | D29: PREVISÃO DE CHEGADA 06:30 | E29: 0.29166667

Sheet 0601
A1: LH | B1: DESTINO | C1: FANOUT | D1: DOCA | E1: CPT | G1: TOTAL DE CARROS EM CURSO PARA O T1 | H1: =SUM(H2,H3) -> 22
A2: LT1Q1601W3BX1 | B2: RJ DUQUE DE CAXIAS | C2: RJ2 | D2: 97 | E2: 0.25 | G2: HUB | H2: 12
A3: LT0Q1701VFLT1 | B3: LIMEIRA | C3: LSP-24 | D3: 9 | E3: 0.25 | G3: SOCS | H3: 10
A4: LT0Q1701VFKA1 | B4: REGISTRO | C4: LSP-40 | D4: 7 | E4: 0.25
A5: LT0Q1701VFM31 | B5: VÁRZEA PAULISTA | C5: LSP-61 | D5: 21 | E5: 0.25
A6: LT0Q1701VFFJ1 | B6: PR CURITIBA | C6: PR1 | D6: 8 | E6: 0.25
A7: LT0Q1701VJKB1 | B7: ATIBAIA | C7: LSP-87 | D7: 14 | E7: 0.27083333
A8: LT0Q1701VGO51 | B8: EMBU DAS ARTES | C8: LSP-36 | D8: 34 | E8: 0.27083333
A9: LT0Q1701VFKW1 | B9: TAUBATÉ | C9: LSP-08 | D9: 20 | E9: 0.27083333 | G9: NÃO DOCADO | H9: 9
A10: LT1Q1601W3C41 | B10: BA SIMOES FILHO | C10: BA2 | D10: 89 | E10: 0.29166667 | G10: DESTINO: LSP-62, LSP-81, LSP-16, LSP-06, LSP-97 PE2, MG2
A11: LT1Q1601W3ED1 | B11: MG BETIM | C11: MG2 | D11: 91 | E11: 0.29166667 | G11: MOTIVO: HUBS NÃO CHEGARAM NO PRAZO DA ETA SOC's NÃO DOCARAM POR FALTA DE PISO
A12: LT1Q1601W3EE1 | B12: MG BETIM | C12: MG2 | D12: NÃO DOCOU | E12: 0.29166667
A13: LT1Q1601W3EB1 | B13: RJ DUQUE DE CAXIAS | C13: RJ2 | D13: 96 | E13: 0.29166667
A14: LT0Q1601VK9J1 | B14: SC ITAJAI | C14: SC1 | D14: 100 | E14: 0.29166667
A15: LT0Q1601VLAD1 | B15: BA SIMOES FILHO | C15: BA2 | D15: 88 | E15: 0.29166667
A16: LT0Q1601VLKE1 | B16: GO GOIANIA | C16: GO2 | D16: 87 | E16: 0.29166667
A17: LT0Q1601VL6Y2 | B17: PE JABOATÃO DOS GUARARAPES | C17: PE2 | D17: NÃO DOCOU | E17: 0.29166667
A18: LT0Q1601VFGG1 | B18: SP CRAVINHOS | C18: SP5 | D18: 95 | E18: 0.29166667
A19: LT0Q1701VKX81 | B19: BARUERI | C19: LSP-81 | D19: NÃO CHEGOU | E19: 0.29166667
A20: LT0Q1701VMD61 | B20: JUNDIAI | C20: LSP-100 | D20: 37 | E20: 0.29166667
A21: LT0Q1701VG7N1 | B21: PIRACICABA | C21: LSP-62 | D21: CHEGA POR VOLTA DE 06:30 | E21: 0.29166667
A22: LT0Q1701VGMW1 | B22: JURUBATUBA | C22: LSP-16 | D22: NÃO CHEGOU | E22: 0.29166667
A23: LT0Q1701VGO11 | B23: PRAIA GRANDE 02 | C23: LSP-63 | D23: 17 | E23: 0.29166667
A24: LT0Q1701VGMR1 | B24: JURUBATUBA | C24: LSP-16 | D24: 32 | E24: 0.29166667
A25: LT0Q1701VGNE1 | B25: GUARUJÁ | C25: LSP-06 | D25: NÃO CHEGOU | E25: 0.3125
A26: LT0Q1701VGN91 | B26: ZIMBA | C26: LSP-74 | D26: 28 | E26: 0.3125
A27: LT0Q1701VGNJ1 | B27: PRAIA GRANDE | C27: LSP-09 | D27: 36 | E27: 0.3125
A28: LT0Q1701VGNO1 | B28: SÃO JOSÉ DOS CAMPOS | C28: LSP-04 | D28: 15 | E28: 0.3125
A29: LT0Q1701VMSI1 | B29: SUZANO BARUEL | C29: LSP-97 | D29: NÃO CHEGOU | E29: 0.3125
A30: LT0Q1701VGGJ1 | B30: GUARULHOS | C30: SP6 | D30: 13 | E30: 0.3125
A31: LT1Q1701W3C11 | B31: PE JABOATÃO DOS GUARARAPES | C31: PE2 | D31: NÃO DOCOU | E31: 0.20833333
A32: LT1Q1601W3EE1 | B32: MG BETIM | C32: MG2 | D32: NÃO DOCOU | E32: 0.29166667
A33: LT0Q1601VL6Y2 | B33: PE JABOATÃO DOS GUARARAPES | C33: PE2 | D33: NÃO DOCOU | E33: 0.29166667

Sheet 0701
A1: LH | B1: DESTINO | C1: FANOUT | D1: DOCA | E1: CPT | G1: TOTAL DE CARROS EM CURSO PARA O T1 | H1: =SUM(H2,H3) -> 30
A2: LT1Q1701W44O1 | B2: BA SIMOES FILHO | C2: BA2 | D2: 89 | E2: 0.25 | G2: HUB | H2: 18
A3: LT0Q1801VFKL1 | B3: GUARATINGUETÁ | C3: LSP-33 | D3: 9 | E3: 0.25 | G3: SOCS | H3: 12
A4: LT0Q1801VFLU1 | B4: LIMEIRA | C4: LSP-24 | D4: 8 | E4: 0.25
A5: LT0Q1801VFKB1 | B5: REGISTRO | C5: LSP-40 | D5: 5 | E5: 0.25
A6: LT0Q1801VR701 | B6: SÃO BERNARDO DO CAMPO | C6: LSP-79 | D6: 44 | E6: 0.25
A7: LT0Q1801VFM41 | B7: VÁRZEA PAULISTA | C7: LSP-61 | D7: 6 | E7: 0.25
A8: LT0Q1801VFFK1 | B8: PR CURITIBA | C8: PR1 | D8: 18 | E8: 0.25
A9: LT0Q1801VJKC1 | B9: ATIBAIA | C9: LSP-87 | D9: 13 | E9: 0.27083333 | G9: NÃO DOCADO | H9: 3
A10: LT0Q1801VGO61 | B10: EMBU DAS ARTES | C10: LSP-36 | D10: 15 | E10: 0.27083333 | G10: DESTINO: LSP-09, LSP-04, RJ2
A11: LT0Q1801VFKX1 | B11: TAUBATÉ | C11: LSP-08 | D11: 7 | E11: 0.27083333 | G11: MOTIVO: HUBS NÃO CHEGARAM NO PRAZO DA ETA SOC's NÃO DOCARAM POR FALTA DE PISO
A12: LT0Q1701VK9K1 | B12: SC ITAJAI | C12: SC1 | D12: 101 | E12: 0.29166667
A13: LT0Q1701VLKH2 | B13: GO GOIANIA | C13: GO2 | D13: 86 | E13: 0.29166667
A14: LT0Q1701VL6X1 | B14: PE JABOATÃO DOS GUARARAPES | C14: PE2 | D14: 49 | E14: 0.29166667
A15: LT0Q1701VL6Z2 | B15: PE JABOATÃO DOS GUARARAPES | C15: PE2 | D15: 99 | E15: 0.29166667
A16: LT0Q1701VFF91 | B16: MG BETIM | C16: MG2 | D16: 91 | E16: 0.29166667
A17: LT0Q1801VKX91 | B17: BARUERI | C17: LSP-81 | D17: 17 | E17: 0.29166667
A18: LT0Q1801VMD71 | B18: JUNDIAI | C18: LSP-100 | D18: 35 | E18: 0.29166667
A19: LT0Q1801VG7O1 | B19: PIRACICABA | C19: LSP-62 | D19: 33 | E19: 0.29166667
A20: LT0Q1801VGO21 | B20: PRAIA GRANDE 02 | C20: LSP-63 | D20: 19 | E20: 0.29166667
A21: LT0Q1801VGMS1 | B21: JURUBATUBA | C21: LSP-16 | D21: 38 | E21: 0.29166667
A22: LT0Q1801VRFC1 | B22: MAUÁ | C22: LSP-64 | D22: 14 | E22: 0.29166667
A23: LT0Q1701VLAG2 | B23: BA SIMOES FILHO | C23: BA2 | D23: 113 | E23: 0.29166667
... A26: LT0Q1801VGNA1 | B26: ZIMBA | C26: LSP-74 | D26: 28 | E26: 0.3125
A27: LT0Q1801VGNK1 | B27: PRAIA GRANDE | C27: LSP-09 | D27: NÃO CHEGOU | E27: 0.3125
A28: LT0Q1801VGNP1 | B28: SÃO JOSÉ CAMPOS | C28: LSP-04 | D28: NÃO CHEGOU | E28: 0.3125
A29: LT0Q1801VREW2 | B29: MOOCA | C29: LSP-13 | D29: 49 | E29: 0.3125
A30: LT0Q1701VFGJ2 | B30: SP CRAVINHOS | C30: SP5 | D30: 94 | E30: 0.375
A31: LT0Q1701VLMH2 | B31: RS GRAVATAI | C31: RS2 | D31: 112 | E31: 0.4375
A32: LT0Q1801VHRE1 | B32: RJ DUQUE DE CAXIAS | C32: RJ2 | D32: NÃO DOCOU | E32: 0.66666667
A33: LT0Q1801VK961 | B33: SC ITAJAI | C33: SC1 | D33: 100 | E33: 0.66666667
A34: LT0Q1801VGGI1 | B34: SP GUARULHOS | C34: SP6 | D34: 16 | E34: 0.20833333

Sheet 0801
A1: LH | B1: DESTINO | C1: FANOUT | D1: DOCA | E1: CPT | G1: TOTAL DE CARROS EM CURSO PARA O T1 | H1: =SUM(H2,H3) -> 23
A2: LT1Q1801W4W81 | B2: PE JABOATÃO DOS GUARARAPES | C2: PE2 | D2: 98 | E2: 0.25 | G2: HUB | H2: 15
A3: LT0Q1901VFKN1 | B3: GUARATINGUETÁ | C3: LSP-33 | D3: 29 | E3: 0.25 | G3: SOCS | H3: 8
A4: LT0Q1901VFKC1 | B4: REGISTRO | C4: LSP-40 | D4: 20 | E4: 0.25
A5: LT0Q1901VFM51 | B5: VÁRZEA PAULISTA | C5: LSP-61 | D5: 27 | E5: 0.25
A6: LT0Q1901VG4Q1 | B6: SÃO BERNARDO DO CAMPO | C6: LSP-79 | D6: 16 | E6: 0.25
A7: LT0Q1901VJKD1 | B7: ATIBAIA | C7: LSP-81 | D7: 15 | E7: 0.375
A8: LT0Q1901VGO71 | B8: EMBU DAS ARTES | C8: LSP-36 | D8: 33 | E8: 0.25
A9: LT0Q1901VFKY1 | B9: TAUBATÉ | C9: LSP-08 | D9: 6 | E9: 0.27083333 | G9: NÃO DOCADO | H9: 10
A10: LT0Q1801VLK02 | B10: GOIANIA | C10: GO2 | D10: 110 | E10: 0.27083333 | G10: DESTINO: LSP-09, LSP-04, LSP-16, LSP-63, SC1, PE2, BA2, RJ2, PR1
A11: LT0Q1801VK9L1 | B11: SC ITAJAI | C11: SC1 | D11: NÃO DOCOU | E11: 0.27083333 | G11: MOTIVO: HUBS NÃO CHEGARAM NO PRAZO DA ETA SOC's NÃO DOCARAM POR FALTA DE PISO
A12: LT0Q1801VLAJ2 | B12: BA SIMOES FILHO | C12: BA2 | D12: NÃO DOCOU | E12: 0.29166667
A13: LT0Q1801VLKK2 | B13: GOIANIA | C13: GO2 | D13: 47 | E13: 0.29166667
A14: LT0Q1801VL701 | B14: PE JABOATÃO DOS GUARARAPES | C14: PE2 | D14: NÃO DOCOU | E14: 0.29166667
A15: LT0Q1801VLMI1 | B15: RS GRAVATAI | C15: RS2 | D15: 114 | E15: 0.29166667
A16: LT0Q1801VLMK2 | B16: RS GRAVATAI | C16: RS2 | D16: 102 | E16: 0.29166667
A17: LT0Q1801VRR01 | B17: RJ DUQUE DE CAXIAS | C17: RJ2 | D17: 96 | E17: 0.29166667
A18: LT0Q1801VLKI1 | B18: GOIANIA | C18: G02 | D18: 87 | E18: 0.29166667
A19: LT0Q1901VKXA1 | B19: BARUERI | C19: LSP-81 | D19: 17 | E19: 0.29166667
A20: LT0Q1901VMD81 | B20: JUNDIAI | C20: LSP-100 | D20: 25 | E20: 0.29166667
A21: LT0Q1901VGMO1 | B21: JURUBATUBA | C21: LSP-16 | D21: NÃO CHEGOU | E21: 0.29166667
A22: LT1Q1801W4DJ1 | B22: RJ DUQUE DE CAXIAS | C22: RJ2 | D22: NÃO DOCOU | E22: 0.29166667
A23: LT0Q1901VG7P1 | B23: PIRACICABA | C23: LSP-64 | D23: 38 | E23: 0.29166667
A24: LT0Q1901VGNY1 | B24: PRAIA GRANDE 02 | C24: LSP-63 | D24: NÃO CHEGOU | E24: 0.29166667
A25: LT0Q1901VGO02 | B25: PRAIA GRANDE 02 | C25: LSP-63 | D25: NÃO CHEGOU | E25: 0.3125
A26: LT0Q1901VGNG1 | B26: GUARUJA | C26: LSP-06 | D26: 32 | E26: 0.3125
A27: LT0Q1901VQZS1 | B27: ITAPEVI | C27: LSP-41 | D27: 44 | E27: 0.3125
A28: LT0Q1901VGNB1 | B28: ZIMBA | C28: LSP-74 | D28: 49 | E28: 0.3125
A29: LT0Q1901VGNL1 | B29: PRAIA GRANDE | C29: LSP-09 | D29: NÃO CHEGOU | E29: 0.3125
A30: LT0Q1901VGNQ1 | B30: SÃO JOSÉ DOS CAMPOS | C30: LSP-04 | D30: NÃO CHEGOU | E30: 0.3125
A31: LT0Q1901VREX1 | B31: MOOCA | C31: LSP-13 | D31: 49 | E31: 0.375
A32: LT0Q1901VRF12 | B32: MOOCA | C32: LSP-13 | D32: 49 | E32: 0.4375
A33: LT0Q1901VMSK1 | B33: SUZANO BARUEL | C33: LSP-97 | D33: 13 | E33: 0.66666667
A34: LT0Q1901VFZW1 | B34: SP SANTANA | C34: SP2 | D34: 23 | E34: 0.31944444
A35: LT0Q1901VFFL1 | B35: PR CURITIBA | C35: PR1 | D35: NÃO CHEGOU | E35: 0.375

Sheet 0901
A1: LH | B1: DESTINO | C1: FANOUT | D1: DOCA | E1: CPT | G1: TOTAL DE CARROS EM CURSO PARA O T1 | H1: =SUM(H2,H3) -> 20
A2: LT0Q1901VLKA2 | B2: GOIANIA 02 | C2: GO2 | D2: 86 | E2: 0.16666667 | G2: HUB | H2: 10
A3: LT1Q1901W6UC1 | B3: SC ITAJAI | C3: SC1 | D3: 100 | E3: 0.25 | G3: SOCS | H3: 10
A4: LT1Q1A01W64N1 | B4: RJ DUQUE DE CAXIAS | C4: RJ2 | D4: 113 | E4: 0.25
A5: LT1Q1A01W6BO1 | B5: RJ DUQUE DE CAXIAS | C5: RJ2 | D5: 96 | E5: 0.25
A6: LT0Q1A01VFKZ1 | B6: TAUBATÉ | C6: LSP-08 | D6: 6 | E6: 0.27083333
A7: LT0Q1901VLKD1 | B7: GOIANIA 02 | C7: GO2 | D7: 87 | E7: 0.29166667
A8: LT0Q1901VL711 | B8: PE JABOATÃO DOS GUARARAPES | C8: PE2 | D8: 5 | E8: 0.29166667
A9: LT0Q1901VLMJ1 | B9: RS GRAVATAI | C9: RS2 | D9: 102 | E9: 0.29166667 | G9: NÃO DOCADO | H9: 5
A10: LT0Q1901VLML2 | B10: RS GRAVATAI | C10: RS2 | D10: 25 | E10: 0.29166667 | G10: DESTINO: LSP-62, LSP-41, LSP-97, BA2, MG2
A11: LT0Q1901VRR21 | B11: RJ DUQUE DE CAXIAS | C11: RJ2 | D11: 97 | E11: 0.29166667 | G11: MOTIVO: HUBS NÃO CHEGARAM NO PRAZO DA ETA SOC's NÃO DOCARAM POR FALTA DE PISO
A12: LT0Q1A01VMD91 | B12: JUNDIAI | C12: LSP-100 | D12: 27 | E12: 0.29166667
A13: LT0Q1A01VGMP1 | B13: JURUBATUBA | C13: LSP-16 | D13: 35 | E13: 0.29166667
A14: LT0Q1A01VG7Q1 | B14: PIRACICABA | C14: LSP-62 | D14: NÃO CHEGOU | E14: 0.29166667
A15: LT0Q1A01VGMU1 | B15: JURUBATUBA | C15: LSP-16 | D15: 17 | E15: 0.29166667
A16: LT0Q1A01VRFG1 | B16: MAUÁ | C16: LSP-64 | D16: 15 | E16: 0.29166667
A17: LT0Q1A01VGNH1 | B17: GUARUJÁ | C17: LSP-06 | D17: 34 | E17: 0.3125
A18: LT0Q1A01VQZV1 | B18: ITAPEVI | C18: LSP-41 | D18: NÃO CHEGOU | E18: 0.3125
A19: LT0Q1A01VGNC1 | B19: ZIMBA | C19: LSP-74 | D19: 28 | E19: 0.3125
A20: LT0Q1A01VGNM1 | B20: PRAIA GRANDE | C20: LSP-09 | D20: 29 | E20: 0.3125
A21: LT0Q1A01VMSL1 | B21: SUZANO BARUEL | C21: LSP-97 | D21: NÃO CHEGOU | E21: 0.3125
A22: LT0Q1A01VRFO1 | B22: VILA GUILHERME | C22: LSP-68 | D22: 45 | E22: 0.33333333
A23: LT0Q1A01VGN21 | B23: CARANDIRU | C23: LSP-18 | D23: 39 | E23: 0.375
A24: LT0Q1901VLA92 | B24: BA SIMOES FILHO | C24: BA2 | D24: 89 | E24: 0.375
A25: LT1Q1901W6U51 | B25: MG BETIM | C25: MG2 | D25: NÃO DOCOU | E25: 0.375
A26: LT0Q1901VLA71 | B26: BA SIMOES FILHO | C26: BA2 | D26: NÃO DOCOU | E26: 0.41666667

Sheet 1201
A1: LH | B1: DESTINO | C1: FANOUT | D1: DOCA | E1: CPT | G1: TOTAL DE CARROS EM CURSO PARA O T1 | H1: =H4 -> 29
A2: LT1Q1DO1WNDV1 | B2: PR CURITIBA | C2: SOC-PR1 | D2: 9 | E2: 0.25 | G2: HUB | H2: =COUNTIF(C:C,"*LSP*") -> 18
A3: LT0Q1D01W9B71 | B3: LIMEIRA | C3: LSP-24 | D3: 22 | E3: 0.25 | G3: SOCS | H3: =COUNTIF(C:C,"*SOC*") -> 16
A4: LT0Q1D01W99S1 | B4: REGISTRO | C4: LSP-40 | D4: NÃO CHEGOU | E4: 0.25 | G4: DOCADO | H4: =COUNTIFS(D:D,">=5",D:D,"<=114") -> 29
A5: LT1Q1C01WNFN1 | B5: PE JABOATÃO DOS GUARARAPES | C5: SOC-PE2 | D5: 99 | E5: 0.25 | G5: NÃO DOCADO | H5: =COUNTIF(D:D,"*NÃO DOCOU*") -> 3
A6: LT1Q1D01WNFN1 | B6: PE JABOATÃO DOS GUARARAPES | C6: SOC-PE2 | D6: 110 | E6: 0.25 | G6: NÃO CHEGOU | H6: =COUNTIF(D:D,"*NÃO CHEGOU*") -> 3
A7: LT0Q1D01WIC51 | B7: GUARATINGUETÁ | C7: LSP-33 | D7: 6 | E7: 0.25 | G7: DRIVER DUPLICADO | H7: =COUNTIF(D:D,"*DRIVER DUPLICADO*") -> 0
A8: LT0Q1D01WD5Z1 | B8: ATIBAIA | C8: LSP-87 | D8: 19 | E8: 0.27083333
A9: LT0Q1D01W9AE1 | B9: TAUBATÉ | C9: LSP-08 | D9: 17 | E9: 0.27083333 | G9: DESTINO: LSP-100, LSP-62, LSP-16, LSP-04
A10: LT0Q1C01WF8B1 | B10: RS GRAVATAI | C10: SOC-RS2 | D10: 102 | E10: 0.29166667 | G10: MOTIVO: HUBS NÃO CHEGARAM NO PRAZO DA ETA SOC's NÃO DOCARAM POR FALTA DE PISO
A11: LT1Q1C01WDUK1 | B11: SC ITAJAI | C11: SOC-SC1 | D11: NÃO DOCOU | E11: 0.29166667
A12: LT0Q1D01WF8G1 | B12: RS GRAVATAI | C12: SOC-RS2 | D12: 102 | E12: 0.29166667
A13: LT0Q1D01WEUE1 | B13: BA SIMOES FILHO | C13: SOC-BA2 | D13: 88 | E13: 0.29166667
A14: LT1Q1D01WOHA1 | B14: SC ITAJAI | C14: SOC-SC1 | D14: 100 | E14: 0.29166667
A15: LT0Q1C01W9521 | B15: SP CRAVINHOS | C15: SOC-SP5 | D15: 94 | E15: 0.29166667
A16: LT0Q1D01WF6B1 | B16: GO GOIANIA | C16: SOC-GO2 | D16: 87 | E16: 0.29166667
A17: LT0Q1D01WEUG2 | B17: BA SIMOES FILHO | C17: SOC-BA2 | D17: 89 | E17: 0.29166667
A18: LT0Q1D01WEHA1 | B18: BARUERI | C18: LSP-81 | D18: 28 | E18: 0.29166667
A19: LT0Q1D01WFXM1 | B19: JUNDIAI | C19: LSP-100 | D19: 23 | E19: 0.29166667
A20: LT0Q1D01WACF1 | B20: JURUBATUBA | C20: LSP-16 | D20: 15 | E20: 0.29166667
A21: LT0Q1D01WACG2 | B21: JURUBATUBA | C21: LSP-16 | D21: 18 | E21: 0.29166667
A22: LT0Q1D01W9X11 | B22: PIRACICABA | C22: LSP-62 | D22: 14 | E22: 0.29166667
A23: LT0Q1D01WADR1 | B23: PRAIA GRANDE 02 | C23: LSP-63 | D23: 29 | E23: 0.29166667
... A26: LT0Q1D01WADA1 | B26: PRAIA GRANDE | C26: LSP-09 | D26: 39 | E26: 0.3125
A27: LT0Q1D01WGB51 | B27: SUZANO | C27: LSP-97 | D27: NÃO CHEGOU | E27: 0.3125
A28: LT0Q1D01W9CG1 | B28: VARZEA PAULISTA | C28: LSP-20 | D28: 16 | E28: 0.3125
A29: LT1Q1C01WNFO1 | B29: RS GRAVATAI | C29: SOC-RS2 | D29: NÃO DOCOU | E29: 0.3125
A30: LT1Q1C01WNE21 | B30: GO GOIANIA | C30: SOC-GO2 | D30: 46 | E30: 0.3125
A31: LT0Q1D01W94H1 | B31: SP CRAVINHOS | C31: SOC-SP5 | D31: 94 | E31: 0.33333333
A32: LT1Q1D01WNQ41 | B32: RJ DUQUE DE CAXIAS | C32: SOC-RJ2 | D32: NÃO CHEGOU | E32: 0.33333333
A33: LT0Q1D01WACA1 | B33: LAPA | C33: LSP-15 | D33: 49 | E33: 0.33333333
A34: LT1Q1D01WNY71 | B34: SP LOUVEIRA | C34: SOC-SP7 | D34: 44 | E34: 0.66666667
A35: LT0Q1D01WIKE1 | B35: MOOCA | C35: LSP-13 | D35: 45 | E35: 0.66666667
A36: LT0Q1D01W92S1 | B36: MG BETIM | C36: MG2 | D36: NÃO DOCOU | E36: 0.66666667

Sheet 1301
A1: LH | B1: DESTINO | C1: FANOUT | D1: DOCA | E1: CPT | G1: TOTAL DE CARROS EM CURSO PARA O T1 | H1: =H4 -> 31
A2: LT1Q1E01WO9G1 | B2: PE JABOATÃO DOS GUARARAPES | C2: SOC-PE2 | D2: 47 | E2: 0.20833333 | G2: HUB | H2: =COUNTIF(C:C,"*LSP*") -> 19
A3: LT1Q1D01WOHH1 | B3: RJ DUQUE DE CAXIAS | C3: SOC-RJ2 | D3: 110 | E3: 0.25 | G3: SOCS | H3: =COUNTIF(C:C,"*SOC*") -> 17
A4: LT0Q1E01W9B81 | B4: LIMEIRA | C4: LSP-24 | D4: 23 | E4: 0.25 | G4: DOCADO | H4: =COUNTIFS(D:D,">=5",D:D,"<=114") -> 31
A5: LT0Q1E01W93W1 | B5: PR CURITIBA | C5: SOC-PR1 | D5: 16 | E5: 0.25 | G5: NÃO DOCADO | H5: =COUNTIF(D:D,"*NÃO DOCOU*") -> 0
A6: LT0Q1E01W9TB1 | B6: SÃO BERNARDO DO CAMPO | C6: LSP-79 | D6: 7 | E6: 0.25 | G6: NÃO CHEGOU | H6: =COUNTIF(D:D,"*NÃO CHEGOU*") -> 4
A7: LT0Q1E01WIC61 | B7: GUARATINGUETÁ | C7: LSP-33 | D7: 17 | E7: 0.25 | G7: DRIVER DUPLICADO | H7: =COUNTIF(D:D,"*DRIVER DUPLICADO*") -> 1
A8: LT0Q1E01WD601 | B8: ATIBAIA | C8: LSP-87 | D8: DRIVER DUPLICADO | E8: 0.27083333
A9: LT0Q1E01WADX1 | B9: EMBU DAS ARTES | C9: LSP-36 | D9: 19 | E9: 0.27083333
A10: LT0Q1E01W9AD1 | B10: TAUBATÉ | C10: LSP-08 | D10: 13 | E10: 0.27083333
A11: LT0Q1D01WEQY2 | B11: PE JABOATÃO DOS GUARARAPES | C11: SOC-PE2 | D11: 98 | E11: 0.29166667
A12: LT0Q1D01WF8G1 | B12: RS GRAVATAI | C12: SOC-RS2 | D12: 102 | E12: 0.29166667
A13: LT0Q1D01WEUE1 | B13: BA SIMOES FILHO | C13: SOC-BA2 | D13: 88 | E13: 0.29166667 | G13: DESTINO: LSP-100, LSP-62, LSP-16, LSP-04
A14: LT1Q1D01WOHA1 | B14: SC ITAJAI | C14: SOC-SC1 | D14: 100 | E14: 0.29166667 | G14: MOTIVO: HUBS NÃO CHEGARAM NO PRAZO DA ETA SOC's NÃO DOCARAM POR FALTA DE PISO
A15: LT0Q1D01WEUG2 | B15: BA SIMOES FILHO | C15: SOC-BA2 | D15: 89 | E15: 0.29166667
A16: LT0Q1D01WF6B1 | B16: GO GOIANIA | C16: SOC-GO2 | D16: 87 | E16: 0.29166667
A17: LT0Q1D01WEQY2 | B17: PE JABOATÃO DOS GUARARAPES | C17: SOC-PE2 | D17: 98 | E17: 0.29166667
A18: LT0Q1E01WEHB1 | B18: BARUERI | C18: LSP-81 | D18: 25 | E18: 0.29166667
A19: LT0Q1E01WFXN1 | B19: JUNDIAI | C19: LSP-100 | D19: NÃO CHEGOU | E19: 0.29166667
A20: LT0Q1E01W9X21 | B20: PIRACICABA | C20: LSP-62 | D20: NÃO CHEGOU | E20: 0.29166667
A21: LT0Q1E01WADS1 | B21: PRAIA GRANDE 02 | C21: LSP-63 | D21: 14 | E21: 0.29166667
A22: LT0Q1E01WACL1 | B22: JURUBATUBA | C22: LSP-16 | D22: NÃO CHEGOU | E22: 0.29166667
A23: LT0Q1E01WACH1 | B23: JURUBATUBA | C23: LSP-16 | D23: 35 | E23: 0.29166667
A24: LT0Q1E01WAD61 | B24: GUARUJÁ | C24: LSP-06 | D24: 34 | E24: 0.3125
A25: LT0Q1E01WAD11 | B25: ZIMBA | C25: LSP-74 | D25: 37 | E25: 0.3125
A26: LT0Q1E01WADB1 | B26: PRAIA GRANDE | C26: LSP-09 | D26: 32 | E26: 0.3125
A27: LT0Q1E01W9CH1 | B27: VÁRZEA PAULISTA | C27: LSP-20 | D27: 27 | E27: 0.3125
A28: LT0Q1E01W97X1 | B28: ITAPEVI | C28: LSP-41 | D28: 46 | E28: 0.3125
A29: LT0Q1E01WADK2 | B29: SÃO JOSÉ DOS CAMPOS | C29: LSP-04 | D29: NÃO CHEGOU | E29: 0.3125
A30: LT0Q1E01WIKG1 | B30: MOOCA | C30: LSP-13 | D30: 49 | E30: 0.3125
A31: LT1Q1D01WNQD1 | B31: MG BETIM | C31: SOC-MG2 | D31: 90 | E31: 0.33333333
